Workbook

Sheet Summary
A1: TEST PLAN SUMMARY
A2: partner-platform-prd-v1.8 | Generated: 2026-05-20
A3: No. | B3: BLOCK | C3: TOTAL | D3: COMPLETED | E3: PASSED | G3: FAILED | I3: NOT STARTED | K3: IN PROGRESS | M3: BLOCKED
E4: Number | F4: Percent | G4: Number | H4: Percent | I4: Number | J4: Percent | K4: Number | L4: Percent | M4: Number | N4: Percent | O4: COMMENT | P4: OWNER
A5: 1 | B5: Partner Platform | C5: =COUNTA('Partner Platform'!I14:I1070) -> 305 | D5: =(E5+G5)/C5 -> 0.53442623 | E5: =COUNTIF('Partner Platform'!I14:I1070,"PASSED") -> 151 | F5: =E5/C5 -> 0.49508197 | G5: =COUNTIF('Partner Platform'!I14:I1070,"FAILED") -> 12 | H5: =G5/C5 -> 0.039344262 | I5: =COUNTIF('Partner Platform'!I14:I1070,"NOT_STARTED") -> 2 | J5: =I5/C5 -> 0.006557377 | K5: =COUNTIF('Partner Platform'!I14:I1070,"IN_PROGRESS") -> 0 | L5: =K5/C5 -> 0 | M5: =COUNTIF('Partner Platform'!I14:I1070,"BLOCKED") -> 140 | N5: =M5/C5 -> 0.45901639 | P5: Trang Le
B6: TOTAL | C6: =SUM(C5) -> 305 | D6: =(E6+G6)/C6 -> 0.53442623 | E6: =SUM(E5) -> 151 | F6: =E6/C6 -> 0.49508197 | G6: =SUM(G5) -> 12 | H6: =G6/C6 -> 0.039344262 | I6: =SUM(H5) -> 0.039344262 | J6: =I6/C6 -> 0.00012899758 | K6: =SUM(K5) -> 0 | L6: =K6/C6 -> 0 | M6: =SUM(M5) -> 140 | N6: =M6/C6 -> 0.45901639
A22: Status | B22: Count
A23: Pass | B23: =COUNTIF('Partner Platform'!H:H,"Pass") -> 0
A24: Fail | B24: =COUNTIF('Partner Platform'!H:H,"Fail") -> 0
A25: Not Started | B25: =COUNTIF('Partner Platform'!H:H,"Not Started") -> 0
A26: In Progress | B26: =COUNTIF('Partner Platform'!H:H,"In Progress") -> 0
A27: Type | B27: Count
A28: Type | B28: Count
A29: UI | B29: =COUNTA('Partner Platform'!B87:B106) -> 8
A30: API | B30: =COUNTA('Partner Platform'!A287:A368) -> 2
A31: Coverage | B31: Count
A32: Automation | B32: Count
A33: Automated | B33: 138
A34: Manual Only | B34: 6
A36: Priority | B36: Count
A37: P1 | B37: =COUNTIF('Partner Platform'!F:F,"P1") -> 0
A38: P2 | B38: =COUNTIF('Partner Platform'!F:F,"P2") -> 0
A39: P3 | B39: =COUNTIF('Partner Platform'!F:F,"P3") -> 0
A40: P4 | B40: =COUNTIF('Partner Platform'!F:F,"P4") -> 0

Sheet Partner Platform
A1: PARTNER PLATFORM — MODULE STATUS SUMMARY
A2: Item | B2: Description | C2: Summary | D2: Manual | E2: Automation
A3: TOTAL | B3: Total number of tests | C3: =SUM(C4:C8) -> 305 | D3: =SUM(D4:D8) -> 305 | E3: =SUM(E4:E8) -> 163
A4: PASSED | B4: Number of tests PASSED | C4: =COUNTIF('Partner Platform'!I14:I1070,"PASSED") -> 151 | D4: =COUNTIF('Partner Platform'!J14:J1070,"PASSED") -> 0 | E4: =COUNTIFS('Partner Platform'!L14:L1070,"PASSED",'Partner Platform'!K14:K1070,"YES") -> 151
A5: FAILED | B5: Number of tests FAILED | C5: =COUNTIF('Partner Platform'!I14:I1070,"FAILED") -> 12 | D5: =COUNTIF('Partner Platform'!J14:J1070,"FAILED") -> 0 | E5: =COUNTIFS('Partner Platform'!L14:L1070,"FAILED",'Partner Platform'!K14:K1070,"YES") -> 12
A6: NOT_STARTED | B6: Number of tests that have not been started | C6: =COUNTIF('Partner Platform'!I14:I1070,"NOT_STARTED") -> 2 | D6: =COUNTIF('Partner Platform'!J14:J1070,"NOT_STARTED") -> 165 | E6: =COUNTIFS('Partner Platform'!L14:L1070,"NOT_STARTED",'Partner Platform'!K14:K1070,"YES") -> 0
A7: IN_PROGRESS | B7: Number of tests currently being tested | C7: =COUNTIF('Partner Platform'!I14:I1070,"IN_PROGRESS") -> 0 | D7: =COUNTIF('Partner Platform'!J14:J1070,"IN_PROGRESS") -> 0 | E7: =COUNTIFS('Partner Platform'!L14:L1070,"IN_PROGRESS",'Partner Platform'!K14:K1070,"YES") -> 0
A8: BLOCKED | B8: Tests that could not be executed | C8: =COUNTIF('Partner Platform'!I14:I1070,"BLOCKED") -> 140 | D8: =COUNTIF('Partner Platform'!J14:J1070,"BLOCKED") -> 140 | E8: =COUNTIFS('Partner Platform'!L14:L1070,"BLOCKED",'Partner Platform'!K14:K1070,"YES") -> 0
A12: Main Section | B12: Main Feature/Function | C12: Test Case Name | D12: Test Case ID | E12: Action | F12: Test Type | G12: Priority | H12: Severity | I12: Status | J12: Manual Status | K12: Auto | L12: Automation Status | M12: Requirement Ref | N12: Docs Refer | O12: Bug ID | P12: Owner | Q12: Note | R12: Test Description | S12: Test Step | T12: Primary Ref
A13: UI
A14: Commissions | B14: Commissions & Payouts | C14: PARTNER_UI_COMMISSIONS_001 | D14: 12060301 | E14: Calculate - Type estimated annual value - Commission projection updates live | F14: Functional | G14: P1 | H14: Critical | I14: =IF(K14="No",J14,IF(OR(J14="FAILED",L14="FAILED"),"FAILED",IF(OR(J14="PASSED",L14="PASSED"),"PASSED",IF(OR(J14="IN_PROGRESS",L14="IN_PROGRESS"),"IN_PROGRESS",IF(OR(J14="BLOCKED",L14="BLOCKED"),"BLOCKED","NOT_STARTED"))))) -> BLOCKED | J14: BLOCKED | K14: NO | L14: NOT_STARTED | M14: §4.4, Risk R2 | N14: partner-platform-prd-v1.8.md | P14: Trang Le | Q14: Type estimated annual value → commission projection updates live (in the deal-register wizard, step 2). Blocked on test data (verified live 2026-07-27): the test partner has no commission rate configured — /resources shows "Commission Rates: No rates configured yet. Contact your programme manager." The projection is Total rate × Estimated ACV, so with an empty rate it computes no value (probed: changing inputs shows no $ projection). Also the ACV isn't a direct input — "Estimated ACV / Rate / Projected commission" are collapsible display sections in the wizard (ACV appears derived from plan × seats), so there's nothing to "type" for a live rate×ACV calc. Unblock when a commission rate is configured for the test partner (via SA rate-table) so the projection produces a verifiable value. | T14: 4.4
C15: PARTNER_UI_COMMISSIONS_002 | D15: 12060302 | E15: View - Commissions page - Earned pending and paid totals are visible | F15: Functional | G15: P1 | H15: Major | I15: =IF(K15="No",J15,IF(OR(J15="FAILED",L15="FAILED"),"FAILED",IF(OR(J15="PASSED",L15="PASSED"),"PASSED",IF(OR(J15="IN_PROGRESS",L15="IN_PROGRESS"),"IN_PROGRESS",IF(OR(J15="BLOCKED",L15="BLOCKED"),"BLOCKED","NOT_STARTED"))))) -> PASSED | J15: NOT_STARTED | K15: YES | L15: PASSED | M15: §4.7 | N15: partner-platform-prd-v1.8.md | P15: Trang Le | Q15: PASSED (TC 12060402), verified 2026-07-28. Dashboard renders 3 KPI cards (Total pipeline ACV / Commission YTD / Active Tenants, each with a value) + 4 sections (Tier & Performance, Territory Assignments, Action Required, Pipeline Snapshot). Read-only; empty data shows "No Data Found". First DASHBOARD content test (establishes DashboardPage). Negative N/A, Idempotency N/A. | R15: Open the Commissions page and confirm the earned/pending/paid summary totals + ledger status tabs render. Read-only: works with an empty ledger (amounts may be $0) — verifies the page structure, not specific data. | S15: **Setup (precondition):** Log in as the channel-partner user; open `/commissions` via the shell and wait for the "Commissions" READY_MARKER; let the data settle. **Test Steps:** 1. The 4 summary totals render, each with a $ amount. → Expected: **Pending Payout**, **Paid YTD**, **Total Earned**, **Clawback Risk** cards each show a $ value (e.g. $0 on an empty ledger). 2. All ledger status tabs are visible. → Expected: **All / Earned / Pending / Approved / Paid / Disputed / Clawback** tabs render. **Expected (overall):** The Commissions page renders its summary totals + all ledger tabs (independent of how many commissions exist). | T15: 4.7
C16: PARTNER_UI_COMMISSIONS_003 | D16: 12060303 | E16: Trace - Commission row detail - Deal close to payment details are visible | F16: Functional | G16: P1 | H16: Major | I16: =IF(K16="No",J16,IF(OR(J16="FAILED",L16="FAILED"),"FAILED",IF(OR(J16="PASSED",L16="PASSED"),"PASSED",IF(OR(J16="IN_PROGRESS",L16="IN_PROGRESS"),"IN_PROGRESS",IF(OR(J16="BLOCKED",L16="BLOCKED"),"BLOCKED","NOT_STARTED"))))) -> BLOCKED | J16: BLOCKED | K16: NO | L16: NOT_STARTED | M16: §4.7, §5.6 | N16: partner-platform-prd-v1.8.md | P16: Trang Le | Q16: The commission ledger is **empty** — the test partner has no **Won** deals, so no commission rows exist ("No commissions yet"). Nothing to open / verify. Data-dependency chain: rate configured (SA_PARTNER_MODULE_009, not deployed) → deal approved (SA deal queue blocked by BUG-025) → deal Won → commission row. Unblock once at least one commission exists in the ledger. | T16: 4.7
C17: PARTNER_UI_COMMISSIONS_004 | D17: 12060304 | E17: Submit - Commission dispute - Dispute is created from one text field | F17: Functional | G17: P1 | H17: Major | I17: =IF(K17="No",J17,IF(OR(J17="FAILED",L17="FAILED"),"FAILED",IF(OR(J17="PASSED",L17="PASSED"),"PASSED",IF(OR(J17="IN_PROGRESS",L17="IN_PROGRESS"),"IN_PROGRESS",IF(OR(J17="BLOCKED",L17="BLOCKED"),"BLOCKED","NOT_STARTED"))))) -> BLOCKED | J17: BLOCKED | K17: NO | L17: NOT_STARTED | M17: §4.7 | N17: partner-platform-prd-v1.8.md | P17: Trang Le | Q17: Same as _003 — no commission rows in the ledger to dispute (partner has no Won deals → empty ledger). Needs a real commission entry first (rate → approved deal → Won). | T17: 4.7
C18: PARTNER_UI_COMMISSIONS_005 | D18: 12060305 | E18: Submit - Product failure waiver - Evidence can be linked and request submitted | F18: Functional | G18: P1 | H18: Critical | I18: =IF(K18="No",J18,IF(OR(J18="FAILED",L18="FAILED"),"FAILED",IF(OR(J18="PASSED",L18="PASSED"),"PASSED",IF(OR(J18="IN_PROGRESS",L18="IN_PROGRESS"),"IN_PROGRESS",IF(OR(J18="BLOCKED",L18="BLOCKED"),"BLOCKED","NOT_STARTED"))))) -> BLOCKED | J18: BLOCKED | K18: NO | L18: NOT_STARTED | M18: §4.7, §5.3 | N18: partner-platform-prd-v1.8.md | P18: Trang Le | Q18: Same as _003/_004 — no clawback-eligible commission row exists (empty ledger). Needs a commission in a clawback-eligible state first. | T18: 4.7
C19: PARTNER_UI_COMMISSIONS_006 | D19: 12060306 | E19: Approve - Commission payout over $10K - Two-eye approval is enforced | F19: Security | G19: P1 | H19: Critical | I19: =IF(K19="No",J19,IF(OR(J19="FAILED",L19="FAILED"),"FAILED",IF(OR(J19="PASSED",L19="PASSED"),"PASSED",IF(OR(J19="IN_PROGRESS",L19="IN_PROGRESS"),"IN_PROGRESS",IF(OR(J19="BLOCKED",L19="BLOCKED"),"BLOCKED","NOT_STARTED"))))) -> BLOCKED | J19: BLOCKED | K19: NO | L19: NOT_STARTED | M19: §5.6, §7.5 | N19: partner-platform-prd-v1.8.md | P19: Trang Le | Q19: Needs (a) a payout > $10K pending approval — which requires a Won deal → commission → payout (empty ledger, blocked as _003), and (b) the two-eye approval UI (SA-side, design PN012) which is **not deployed** on staging. Unblock when both the payout data + the two-eye approval UI exist. | T19: 5.6
C20: PARTNER_UI_COMMISSIONS_007 | D20: 12060307 | E20: Display - Clawback notification - Policy terms and product-failure waiver path are visible | F20: Functional | G20: P1 | H20: Major | I20: =IF(K20="No",J20,IF(OR(J20="FAILED",L20="FAILED"),"FAILED",IF(OR(J20="PASSED",L20="PASSED"),"PASSED",IF(OR(J20="IN_PROGRESS",L20="IN_PROGRESS"),"IN_PROGRESS",IF(OR(J20="BLOCKED",L20="BLOCKED"),"BLOCKED","NOT_STARTED"))))) -> BLOCKED | J20: BLOCKED | K20: NO | L20: NOT_STARTED | M20: §4.7, §5.3 | N20: partner-platform-prd-v1.8.md | P20: Trang Le | Q20: The SA Commission **configuration** view (which holds Clawback settings + the Waiver Review Queue) is **not deployed on staging** (re-verified 2026-07-30, same finding as _009/_010: no "View configuration" entry on `/partners/commissions`, config routes 404). An earlier note here checked the partner-portal `/commissions` (its "Clawback" tab only filters the empty ledger) — the actual clawback-policy/waiver experience is SA-side per PN021. Unblock when FE deploys the Commission configuration view. | T20: 4.7
C21: PARTNER_UI_COMMISSIONS_008 | D21: 12060308 | E21: Ask - Blazey commission question - Contextual answer is returned | F21: Functional | G21: P2 | H21: Major | I21: =IF(K21="No",J21,IF(OR(J21="FAILED",L21="FAILED"),"FAILED",IF(OR(J21="PASSED",L21="PASSED"),"PASSED",IF(OR(J21="IN_PROGRESS",L21="IN_PROGRESS"),"IN_PROGRESS",IF(OR(J21="BLOCKED",L21="BLOCKED"),"BLOCKED","NOT_STARTED"))))) -> BLOCKED | J21: BLOCKED | K21: NO | L21: NOT_STARTED | M21: §4.3, §10 | N21: partner-platform-prd-v1.8.md | P21: Trang Le | Q21: Depends on the **Blazey AI assistant** (deferred AI feature) + real commission context data. The assistant is not available/testable on the current build, and the ledger is empty (no commission context). Unblock when Blazey ships + commission data exists. | T21: 46305
C22: PARTNER_UI_COMMISSIONS_009 | D22: 12060309 | E22: Edit - Payout details by region - Correct payment methods are available | F22: Security | G22: P2 | H22: Major | I22: =IF(K22="No",J22,IF(OR(J22="FAILED",L22="FAILED"),"FAILED",IF(OR(J22="PASSED",L22="PASSED"),"PASSED",IF(OR(J22="IN_PROGRESS",L22="IN_PROGRESS"),"IN_PROGRESS",IF(OR(J22="BLOCKED",L22="BLOCKED"),"BLOCKED","NOT_STARTED"))))) -> BLOCKED | J22: BLOCKED | K22: NO | L22: NOT_STARTED | M22: §4.7 | N22: partner-platform-prd-v1.8.md | P22: Trang Le | Q22: No payout/banking-details edit UI found on the partner build — `/commissions` is a read-only ledger; a payout-details/settings screen (per region) was not located. Needs the payout-details UI + region fixtures. Unblock when the payout-details screen is available. | T22: 4.7
C23: PARTNER_UI_COMMISSIONS_010 | E23: Process - Commission clawback on early churn - Clawback is applied | F23: Functional | G23: P1 | H23: Major | I23: =IF(K23="No",J23,IF(OR(J23="FAILED",L23="FAILED"),"FAILED",IF(OR(J23="PASSED",L23="PASSED"),"PASSED",IF(OR(J23="IN_PROGRESS",L23="IN_PROGRESS"),"IN_PROGRESS",IF(OR(J23="BLOCKED",L23="BLOCKED"),"BLOCKED","NOT_STARTED"))))) -> BLOCKED | J23: BLOCKED | K23: NO | L23: NOT_STARTED | M23: §5.6 | N23: partner-platform-prd-v1.8.md | P23: Trang Le | Q23: Figma design: [PN013] Process commission clawback on early churn. Candidate TC — not yet in the plan. Verified live 2026-07-31 on the SA commission ledger (stgsa `/partners/commissions`): the ledger is **empty** ("No Data Found", 0 commissions) so there is no commission to clawback, and there is **no process-clawback action** in the UI (only a "Clawback Exposure" summary card + a Clawback status filter tab — no per-row "process clawback" control; design PN013 not deployed). Needs the full chain — rate configured → deal approved (blocked by BUG-025) → deal Won → commission — plus the process-clawback UI. Unblock when a churned-client commission exists + the process-clawback UI ships. | T23: 46178
B24: Commission Display | C24: PARTNER_UI_COMMISSIONS_011 | E24: Display - Reseller deal commission - Reseller rate shown, not referral rate | F24: Functional | G24: P1 | H24: Major | I24: =IF(K24="No",J24,IF(OR(J24="FAILED",L24="FAILED"),"FAILED",IF(OR(J24="PASSED",L24="PASSED"),"PASSED",IF(OR(J24="IN_PROGRESS",L24="IN_PROGRESS"),"IN_PROGRESS",IF(OR(J24="BLOCKED",L24="BLOCKED"),"BLOCKED","NOT_STARTED"))))) -> BLOCKED | J24: BLOCKED | K24: NO | L24: NOT_STARTED | M24: §3 Scenario B, §4.7, §5.3 | N24: partner-platform-prd-v1.8.md | P24: Trang Le | Q24: Needs a **Reseller-type partner** with a **Won reseller deal** and a reseller rate configured. The test partner is type Channel, the register wizard fixes deal type to Referral, and there is no configured rate / Won deal — so no reseller commission entry exists to verify. Unblock with a reseller partner + Won reseller deal + rate. | T24: 46207
B25: Invoice & Billing | C25: PARTNER_UI_COMMISSIONS_012 | E25: Invoice - Reseller deal close - Invoice generated for partner not end-client | F25: Functional | G25: P1 | H25: Critical | I25: =IF(K25="No",J25,IF(OR(J25="FAILED",L25="FAILED"),"FAILED",IF(OR(J25="PASSED",L25="PASSED"),"PASSED",IF(OR(J25="IN_PROGRESS",L25="IN_PROGRESS"),"IN_PROGRESS",IF(OR(J25="BLOCKED",L25="BLOCKED"),"BLOCKED","NOT_STARTED"))))) -> BLOCKED | J25: BLOCKED | K25: NO | L25: NOT_STARTED | M25: §3 Scenario B, §5.3 | N25: partner-platform-prd-v1.8.md | P25: Trang Le | Q25: Same dependency as _011 — needs a reseller partner + Won reseller deal that has passed commission processing, plus the invoice/billing UI (not seen on the partner build). Unblock with the reseller data + invoice UI. | T25: 3-B
A26: Dashboard | B26: Home KPIs & Actions | C26: PARTNER_UI_DASHBOARD_001 | D26: 12060401 | E26: View - Partner shell loads for channel partner - Dashboard is displayed | F26: Functional | G26: P1 | H26: Critical | I26: =IF(K26="No",J26,IF(OR(J26="FAILED",L26="FAILED"),"FAILED",IF(OR(J26="PASSED",L26="PASSED"),"PASSED",IF(OR(J26="IN_PROGRESS",L26="IN_PROGRESS"),"IN_PROGRESS",IF(OR(J26="BLOCKED",L26="BLOCKED"),"BLOCKED","NOT_STARTED"))))) -> PASSED | J26: NOT_STARTED | K26: YES | L26: PASSED | M26: §4.1, §4.2 | N26: partner-platform-prd-v1.8.md | P26: Trang Le | Q26: PASSED — verified 2026-07-28 (TC 12060401). Access-control style shell test: proves the partner portal exposes only partner routes and the Dashboard is the default landing page. Negative counterpart: N/A — access-control assertion is embedded (asserts SA-only routes are absent). Idempotency: N/A — read-only view. | R26: The partner shell loads for a channel-partner user and lands on the Dashboard. Confirms the shell chrome (brand + nav + profile), partner-only navigation (no SA/tenant-only routes leaked), and Dashboard content loading with no error/authorization banner. | S26: **Setup (precondition):** Log in as the channel-partner user; navigate to the portal root `/` (Dashboard is the default page) and wait for the "Tier & Performance" READY_MARKER. **Test Steps:** 1. Partner shell chrome renders. → Expected: the "PARTNER PORTAL" brand, ≥5 sidebar nav links, and the "Open profile menu" control are visible. 2. Only partner navigation is exposed. → Expected: partner routes `/dashboard`, `/deals`, `/commissions` present; NO SA/tenant-only routes (`/tenants`, `/billing`, `/plans`, `/partners`, `/connectors`, `/auditLog`). 3. Dashboard content loads with no error/authorization banner. → Expected: no "Something went wrong" / "not authorized" / "Unauthorized" / "403" / "Access denied"; the "Tier & Performance" panel is visible in `<main>`. **Expected (overall):** The partner shell loads for the channel partner with the Dashboard active, partner-scoped nav only, and no error/auth banner. | T26: 46057
C27: PARTNER_UI_DASHBOARD_002 | D27: 12060402 | E27: Render - Dashboard KPI cards available - Actionable metrics are visible | F27: Functional | G27: P1 | H27: Major | I27: =IF(K27="No",J27,IF(OR(J27="FAILED",L27="FAILED"),"FAILED",IF(OR(J27="PASSED",L27="PASSED"),"PASSED",IF(OR(J27="IN_PROGRESS",L27="IN_PROGRESS"),"IN_PROGRESS",IF(OR(J27="BLOCKED",L27="BLOCKED"),"BLOCKED","NOT_STARTED"))))) -> PASSED | J27: NOT_STARTED | K27: YES | L27: PASSED | M27: §4.3 | N27: partner-platform-prd-v1.8.md | P27: Trang Le | Q27: PASSED — verified 2026-07-28 (TC 12060402). First DASHBOARD content test — establishes the `DashboardPage` page-object (KPI cards, sections). Empty partner data shows "No Data Found" in Action Required / Pipeline Snapshot. Negative counterpart: N/A — read-only view. Idempotency: N/A. | R27: Open the partner Dashboard and confirm the KPI metric cards + main section panels render. Read-only: works with empty data (values may be 0 / USD 0) — verifies the cards render, not specific figures. | S27: **Setup (precondition):** Log in as the channel-partner user; open `/dashboard` via the shell and wait for the "Tier & Performance" READY_MARKER. **Test Steps:** 1. KPI cards render, each with a metric value. → Expected: **Total pipeline ACV**, **Commission YTD**, **Active Tenants** each show a value (e.g. "USD 0" / 0). 2. The main dashboard sections render. → Expected: **Tier & Performance**, **Territory Assignments**, **Action Required**, **Pipeline Snapshot** panels are visible. **Expected (overall):** The dashboard renders its KPI metric cards + all main sections (independent of the data). | T27: 4.3
C28: PARTNER_UI_DASHBOARD_003 | D28: 12060403 | E28: Render - Tier progress exists on dashboard - Progress to next tier is visible | F28: Functional | G28: P1 | H28: Major | I28: =IF(K28="No",J28,IF(OR(J28="FAILED",L28="FAILED"),"FAILED",IF(OR(J28="PASSED",L28="PASSED"),"PASSED",IF(OR(J28="IN_PROGRESS",L28="IN_PROGRESS"),"IN_PROGRESS",IF(OR(J28="BLOCKED",L28="BLOCKED"),"BLOCKED","NOT_STARTED"))))) -> FAILED | J28: NOT_STARTED | K28: YES | L28: FAILED | M28: §2.1, §4.3 | N28: partner-platform-prd-v1.8.md | O28: BUG-UI-014 | P28: Trang Le | Q28: PASSED — verified 2026-07-28 (TC 12060403; current=SELECT, working towards ADVANCED, ARR USD 0). **Plan-vs-live:** the plan also lists a **threshold target**, a **progress bar**, and a **remaining delta** — this build does NOT render those (no `role=progressbar` element, no threshold/remaining text); it shows current tier + next-tier copy + ARR + deals/win-rate. The test asserts what the UI actually renders. Negative counterpart: N/A — read-only view. Idempotency: N/A. | R28: The dashboard Tier Progress component shows progress to the next tier. Read-only. | S28: **Setup (precondition):** Log in as the channel-partner user; open `/dashboard` and wait for the "Tier & Performance" READY_MARKER. **Test Steps:** 1. Tier Progress shows the current tier + "working towards" the next tier + current ARR. → Expected: "Tier Progress" present; the **current tier** (SELECT/ADVANCED/PREMIER), the **"Working towards \<next tier\>"** copy, and **T12M ARR** are shown. 2. Progress metrics are shown. → Expected: the **deal count** and **Win rate** are shown in the tier progress panel. **Expected (overall):** Progress toward the next tier is visible (current tier + next-tier copy + ARR + metrics). | T28: 4.3
C29: PARTNER_UI_DASHBOARD_004 | D29: 12060404 | E29: Render - Action Required list has pending tasks - Partner sees next actions | F29: Functional | G29: P1 | H29: Major | I29: =IF(K29="No",J29,IF(OR(J29="FAILED",L29="FAILED"),"FAILED",IF(OR(J29="PASSED",L29="PASSED"),"PASSED",IF(OR(J29="IN_PROGRESS",L29="IN_PROGRESS"),"IN_PROGRESS",IF(OR(J29="BLOCKED",L29="BLOCKED"),"BLOCKED","NOT_STARTED"))))) -> BLOCKED | J29: BLOCKED | K29: NO | L29: NOT_STARTED | M29: §4.3 | N29: partner-platform-prd-v1.8.md | P29: Trang Le | Q29: No fixture / seeding path to make the Action Required list non-empty. The test partner (channel-partner) has empty data — the section renders its graceful empty state ("Action Required · No Data Found · Looks like there's nothing here yet"). Action-Required items are DERIVED (renewals due, deals needing partner action); there is no partner-side API to seed them, and the existing QA-AUTO deals (pending SA approval) do not surface here. The "has pending tasks" positive path cannot be verified until a partner account with real action items (or a seed hook) is available. Revisit with a data-seeded partner. | T29: 4.3
C30: PARTNER_UI_DASHBOARD_005 | D30: 12060405 | E30: Calculate - Tier qualification dashboard - T12M ARR threshold and next-tier delta are visible | F30: Functional | G30: P1 | H30: Major | I30: =IF(K30="No",J30,IF(OR(J30="FAILED",L30="FAILED"),"FAILED",IF(OR(J30="PASSED",L30="PASSED"),"PASSED",IF(OR(J30="IN_PROGRESS",L30="IN_PROGRESS"),"IN_PROGRESS",IF(OR(J30="BLOCKED",L30="BLOCKED"),"BLOCKED","NOT_STARTED"))))) -> FAILED | J30: NOT_STARTED | K30: YES | L30: FAILED | M30: §2.1, §4.3 | N30: partner-platform-prd-v1.8.md | O30: BUG-UI-007,BUG-UI-014 | P30: Trang Le | Q30: FAILED by design (be_gap) 2026-07-28 (TC 12060405). Build renders only current tier + "Working towards <next>" + current ARR + deal/win-rate ("0/0 deals"); NO ARR threshold, NO remaining delta, NO progress bar (no role=progressbar). Assertion fails with "confirm with BE". Complements DASHBOARD_003 (asserts only what UI renders); this TC pins the missing tier-qualification math. Excluded from merge gate. Negative/Idempotency: N/A (read-only calc). | R30: PARTNER_UI_DASHBOARD_001 | S30: **Setup (precondition):** Log in as the channel-partner user; open `/dashboard` and wait for the "Tier & Performance" READY_MARKER; locate the Tier Progress component. **Test Steps:** 1. Current tier + current T12M ARR are shown (baseline). → Expected: current tier (SELECT/ADVANCED/PREMIER) + "T12M ARR" are shown. **(PASSES — build renders these.)** 2. Next-tier T12M ARR threshold target + remaining delta are shown. → Expected: a threshold/target/remaining figure toward the next tier is shown. **(FAILS — not rendered.)** 3. A progress bar toward the next-tier threshold is shown. → Expected: a `role=progressbar` / `<progress>` element is present. **(Would FAIL — none rendered.)** **Expected (overall):** The tier-qualification threshold + remaining delta + progress bar are visible. | T30: 4.3
B31: Tier Progress | C31: PARTNER_UI_DASHBOARD_006 | D31: 12060406 | E31: Warn - Tier downgrade pending - 30-day notice and grace quarter are displayed | F31: Functional | G31: P1 | H31: Major | I31: =IF(K31="No",J31,IF(OR(J31="FAILED",L31="FAILED"),"FAILED",IF(OR(J31="PASSED",L31="PASSED"),"PASSED",IF(OR(J31="IN_PROGRESS",L31="IN_PROGRESS"),"IN_PROGRESS",IF(OR(J31="BLOCKED",L31="BLOCKED"),"BLOCKED","NOT_STARTED"))))) -> BLOCKED | J31: BLOCKED | K31: NO | L31: NOT_STARTED | M31: §2.1, §5.5 | N31: partner-platform-prd-v1.8.md | P31: Trang Le | Q31: The test partner is not in a **tier-downgrade-pending** state, and there is no way to seed one (tier downgrade is derived from T12M ARR falling below the current tier's threshold over a grace quarter). With no partner in that state, the 30-day-notice / grace-quarter warning cannot be triggered or verified. Also depends on the tier-qualification math that _005 showed is not fully rendered. Unblock with a partner fixture in the downgrade-pending state (+ the warning UI). | T31: 5.5
B32: Home KPIs & Actions | C32: PARTNER_UI_DASHBOARD_007 | D32: 12060407 | E32: Validate - Dashboard hides vanity metrics - Only actionable/clickable values are shown | F32: Negative | G32: P3 | H32: Minor | I32: =IF(K32="No",J32,IF(OR(J32="FAILED",L32="FAILED"),"FAILED",IF(OR(J32="PASSED",L32="PASSED"),"PASSED",IF(OR(J32="IN_PROGRESS",L32="IN_PROGRESS"),"IN_PROGRESS",IF(OR(J32="BLOCKED",L32="BLOCKED"),"BLOCKED","NOT_STARTED"))))) -> PASSED | J32: NOT_STARTED | K32: YES | L32: PASSED | M32: §4.3 | N32: partner-platform-prd-v1.8.md | P32: Trang Le | Q32: CODE COMPLETE, run PENDING VERIFY (TC 12060407) 2026-07-28. No green run yet: staging partner dashboard MFE degraded ~15:35 (<main>/"Tier & Performance" not rendering within 90s; earlier probes rendered in ~8s — staging outage, not a test defect). Re-run when staging recovers. Negative TC by design. Idempotency N/A (read-only). | R32: (Negative guard) Dashboard hides vanity metrics — per PRD §4.3 the first dashboard view shows ONLY actionable/decision-supporting values (pipeline ACV, commission, active tenants, tier progress, action items, pipeline snapshot) and must NOT surface non-actionable vanity metrics (page/profile views, impressions, followers, bounce rate, login counts). | S32: 1. Log in as channel-partner; open /dashboard, wait for "Tier & Performance" → Expected: dashboard ready. 2. Only actionable KPI metrics shown → Expected: Total pipeline ACV, Commission YTD, Active Tenants visible. 3. No vanity metrics present → Expected: none of {page views, profile views, impressions, followers, bounce rate, time on page, click-through, logins, vanity} in <main>. 4. Page hierarchy still highlights actionable sections → Expected: Action Required, Tier Progress, Pipeline Snapshot visible. | T32: 4.3
B33: Blazey AI Assistant | C33: PARTNER_UI_DASHBOARD_008 | D33: 12060408 | E33: Ask - Blazey deal status question on dashboard - Current deal stage and assigned rep contact are returned | F33: Functional | G33: P2 | H33: Major | I33: =IF(K33="No",J33,IF(OR(J33="FAILED",L33="FAILED"),"FAILED",IF(OR(J33="PASSED",L33="PASSED"),"PASSED",IF(OR(J33="IN_PROGRESS",L33="IN_PROGRESS"),"IN_PROGRESS",IF(OR(J33="BLOCKED",L33="BLOCKED"),"BLOCKED","NOT_STARTED"))))) -> BLOCKED | J33: BLOCKED | K33: NO | L33: NOT_STARTED | M33: §4.3, §10.10 | N33: partner-platform-prd-v1.8.md | P33: Trang Le | Q33: Depends on the **Blazey AI assistant** (deferred AI feature) — the widget is not available/testable on the current build — plus real deal data for the partner. Unblock when Blazey ships + the partner has deals. | T33: 4.3
C34: PARTNER_UI_DASHBOARD_009 | D34: 12060409 | E34: Ask - Blazey tier projection question on dashboard - ARR needed and timeline to next tier are displayed | F34: Functional | G34: P2 | H34: Major | I34: =IF(K34="No",J34,IF(OR(J34="FAILED",L34="FAILED"),"FAILED",IF(OR(J34="PASSED",L34="PASSED"),"PASSED",IF(OR(J34="IN_PROGRESS",L34="IN_PROGRESS"),"IN_PROGRESS",IF(OR(J34="BLOCKED",L34="BLOCKED"),"BLOCKED","NOT_STARTED"))))) -> BLOCKED | J34: BLOCKED | K34: NO | L34: NOT_STARTED | M34: §4.3, §10.10 | N34: partner-platform-prd-v1.8.md | P34: Trang Le | Q34: Same as _008 — depends on the Blazey AI assistant (deferred) + tier data. Note the tier-qualification figures it would quote (threshold/gap) are also the ones _005 showed the UI doesn't fully render yet. Unblock when Blazey ships. | T34: 4.3
A35: My Clients | B35: Client Health & MSP | C35: PARTNER_UI_MY_CLIENTS_001 | E35: Click - Action Required renewal CTA - Renewal registration flow opens | F35: Functional | G35: P1 | H35: Major | I35: =IF(K35="No",J35,IF(OR(J35="FAILED",L35="FAILED"),"FAILED",IF(OR(J35="PASSED",L35="PASSED"),"PASSED",IF(OR(J35="IN_PROGRESS",L35="IN_PROGRESS"),"IN_PROGRESS",IF(OR(J35="BLOCKED",L35="BLOCKED"),"BLOCKED","NOT_STARTED"))))) -> BLOCKED | J35: BLOCKED | K35: NO | L35: NOT_STARTED | M35: §4.3, §4.6 | N35: partner-platform-prd-v1.8.md | P35: Trang Le | Q35: module not deployed | T35: 4.6
C36: PARTNER_UI_MY_CLIENTS_002 | E36: List - Open My Clients - Post-close clients are displayed | F36: Functional | G36: P1 | H36: Major | I36: =IF(K36="No",J36,IF(OR(J36="FAILED",L36="FAILED"),"FAILED",IF(OR(J36="PASSED",L36="PASSED"),"PASSED",IF(OR(J36="IN_PROGRESS",L36="IN_PROGRESS"),"IN_PROGRESS",IF(OR(J36="BLOCKED",L36="BLOCKED"),"BLOCKED","NOT_STARTED"))))) -> BLOCKED | J36: BLOCKED | K36: NO | L36: NOT_STARTED | M36: §4.6 | N36: partner-platform-prd-v1.8.md | P36: Trang Le | Q36: module not deployed | T36: 4.6
C37: PARTNER_UI_MY_CLIENTS_003 | E37: Open - Client health detail - ARR, renewal, usage, tickets, and CSM are visible | F37: Functional | G37: P1 | H37: Critical | I37: =IF(K37="No",J37,IF(OR(J37="FAILED",L37="FAILED"),"FAILED",IF(OR(J37="PASSED",L37="PASSED"),"PASSED",IF(OR(J37="IN_PROGRESS",L37="IN_PROGRESS"),"IN_PROGRESS",IF(OR(J37="BLOCKED",L37="BLOCKED"),"BLOCKED","NOT_STARTED"))))) -> BLOCKED | J37: BLOCKED | K37: NO | L37: NOT_STARTED | M37: §1.3, §4.6 | N37: partner-platform-prd-v1.8.md | P37: Trang Le | Q37: module not deployed | T37: 4.6
C38: PARTNER_UI_MY_CLIENTS_004 | E38: Register - Renewal deal from client detail - Renewal context is prefilled | F38: Functional | G38: P1 | H38: Major | I38: =IF(K38="No",J38,IF(OR(J38="FAILED",L38="FAILED"),"FAILED",IF(OR(J38="PASSED",L38="PASSED"),"PASSED",IF(OR(J38="IN_PROGRESS",L38="IN_PROGRESS"),"IN_PROGRESS",IF(OR(J38="BLOCKED",L38="BLOCKED"),"BLOCKED","NOT_STARTED"))))) -> BLOCKED | J38: BLOCKED | K38: NO | L38: NOT_STARTED | M38: §3 Scenario F, §4.6 | N38: partner-platform-prd-v1.8.md | P38: Trang Le | Q38: module not deployed | T38: 4.6
C39: PARTNER_UI_MY_CLIENTS_005 | E39: Add - MSP managed client - Provisioning form is shown | F39: Functional | G39: P1 | H39: Critical | I39: =IF(K39="No",J39,IF(OR(J39="FAILED",L39="FAILED"),"FAILED",IF(OR(J39="PASSED",L39="PASSED"),"PASSED",IF(OR(J39="IN_PROGRESS",L39="IN_PROGRESS"),"IN_PROGRESS",IF(OR(J39="BLOCKED",L39="BLOCKED"),"BLOCKED","NOT_STARTED"))))) -> BLOCKED | J39: BLOCKED | K39: NO | L39: NOT_STARTED | M39: §3 Scenario G, §7.3 | N39: partner-platform-prd-v1.8.md | P39: Trang Le | Q39: module not deployed | T39: 3-G
C40: PARTNER_UI_MY_CLIENTS_006 | E40: Toggle - MSP ticket consent default - Consent is off by default | F40: Security | G40: P1 | H40: Major | I40: =IF(K40="No",J40,IF(OR(J40="FAILED",L40="FAILED"),"FAILED",IF(OR(J40="PASSED",L40="PASSED"),"PASSED",IF(OR(J40="IN_PROGRESS",L40="IN_PROGRESS"),"IN_PROGRESS",IF(OR(J40="BLOCKED",L40="BLOCKED"),"BLOCKED","NOT_STARTED"))))) -> BLOCKED | J40: BLOCKED | K40: NO | L40: NOT_STARTED | M40: §3 Scenario G, §7.3, §9.2 | N40: partner-platform-prd-v1.8.md | P40: Trang Le | Q40: module not deployed | T40: 3-G
C41: PARTNER_UI_MY_CLIENTS_007 | E41: Filter - Renewal This Quarter - Only qualifying clients are shown | F41: Functional | G41: P2 | H41: Major | I41: =IF(K41="No",J41,IF(OR(J41="FAILED",L41="FAILED"),"FAILED",IF(OR(J41="PASSED",L41="PASSED"),"PASSED",IF(OR(J41="IN_PROGRESS",L41="IN_PROGRESS"),"IN_PROGRESS",IF(OR(J41="BLOCKED",L41="BLOCKED"),"BLOCKED","NOT_STARTED"))))) -> BLOCKED | J41: BLOCKED | K41: NO | L41: NOT_STARTED | M41: §4.6 | N41: partner-platform-prd-v1.8.md | P41: Trang Le | Q41: module not deployed | T41: 4.6
C42: PARTNER_UI_MY_CLIENTS_008 | E42: Filter - Health At Risk - At-risk clients are shown | F42: Functional | G42: P2 | H42: Major | I42: =IF(K42="No",J42,IF(OR(J42="FAILED",L42="FAILED"),"FAILED",IF(OR(J42="PASSED",L42="PASSED"),"PASSED",IF(OR(J42="IN_PROGRESS",L42="IN_PROGRESS"),"IN_PROGRESS",IF(OR(J42="BLOCKED",L42="BLOCKED"),"BLOCKED","NOT_STARTED"))))) -> BLOCKED | J42: BLOCKED | K42: NO | L42: NOT_STARTED | M42: §1.3, §4.6 | N42: partner-platform-prd-v1.8.md | P42: Trang Le | Q42: module not deployed | T42: 4.6
C43: PARTNER_UI_MY_CLIENTS_009 | E43: Search - Find client by name - Matching clients are displayed | F43: Functional | G43: P2 | H43: Major | I43: =IF(K43="No",J43,IF(OR(J43="FAILED",L43="FAILED"),"FAILED",IF(OR(J43="PASSED",L43="PASSED"),"PASSED",IF(OR(J43="IN_PROGRESS",L43="IN_PROGRESS"),"IN_PROGRESS",IF(OR(J43="BLOCKED",L43="BLOCKED"),"BLOCKED","NOT_STARTED"))))) -> BLOCKED | J43: BLOCKED | K43: NO | L43: NOT_STARTED | M43: §4.6 | N43: partner-platform-prd-v1.8.md | P43: Trang Le | Q43: module not deployed | T43: 4.6
...

Sheet Regression Suite
A1: REGRESSION SUITE — MODULE STATUS SUMMARY
A2: Item | B2: Description | C2: Summary
A3: TOTAL | B3: Total number of tests | C3: =SUM(C4:C8) -> 119
A4: PASSED | B4: Number of tests PASSED | C4: =COUNTIF('Regression Suite'!G13:G999,"PASSED") -> 0
A5: FAILED | B5: Number of tests FAILED | C5: =COUNTIF('Regression Suite'!G13:G999,"FAILED") -> 0
A6: NOT_STARTED | B6: Number of tests not started | C6: =COUNTIF('Regression Suite'!G13:G999,"NOT_STARTED") -> 118
A7: IN_PROGRESS | B7: Number currently being tested | C7: =COUNTIF('Regression Suite'!G13:G999,"IN_PROGRESS") -> 0
A8: BLOCKED | B8: Tests that could not be executed | C8: =COUNTIF('Regression Suite'!G13:G999,"BLOCKED") -> 1
A11: REGRESSION SUITE — P1 Test Cases (All Modules)
A12: Auto-compiled from all P1 TCs across active modules | Run before every release
A13: TC ID | B13: Module | C13: Test Case Name | D13: Type (UI/API) | E13: Priority | F13: Owner | G13: Automation Status | H13: Automation TC Mapping
A14: Partner Platform
A15: PARTNER_UI_PARTNER_PORTAL_SHELL_001 | B15: Partner Platform | C15: Navigate - Open main menu routes - Correct page content is shown | D15: UI | E15: P1 | F15: Trang Le | G15: NOT_STARTED | H15: tests/ui/partner_002
A16: PARTNER_UI_DASHBOARD_001 | B16: Partner Platform | C16: View - Partner shell loads for channel partner - Dashboard is displayed | D16: UI | E16: P1 | F16: Trang Le | G16: NOT_STARTED | H16: tests/ui/partner_001
A17: PARTNER_UI_DASHBOARD_002 | B17: Partner Platform | C17: Render - Dashboard KPI cards available - Actionable metrics are visible | D17: UI | E17: P1 | F17: Trang Le | G17: NOT_STARTED | H17: tests/ui/partner_003
A18: PARTNER_UI_DASHBOARD_003 | B18: Partner Platform | C18: Render - Tier progress exists on dashboard - Progress to next tier is visible | D18: UI | E18: P1 | F18: Trang Le | G18: NOT_STARTED | H18: tests/ui/partner_004
A19: PARTNER_UI_DASHBOARD_004 | B19: Partner Platform | C19: Render - Action Required list has pending tasks - Partner sees next actions | D19: UI | E19: P1 | F19: Trang Le | G19: NOT_STARTED | H19: tests/ui/partner_005
A20: PARTNER_UI_DASHBOARD_005 | B20: Partner Platform | C20: Calculate - Tier qualification dashboard - T12M ARR threshold and next-tier delta are visible | D20: UI | E20: P1 | F20: Trang Le | G20: NOT_STARTED
A21: PARTNER_UI_DASHBOARD_006 | B21: Partner Platform | C21: Warn - Tier downgrade pending - 30-day notice and grace quarter are displayed | D21: UI | E21: P1 | F21: Trang Le | G21: NOT_STARTED
A22: PARTNER_UI_MY_PIPELINE_001 | B22: Partner Platform | C22: Register - Enter valid company details - Wizard advances to contact step | D22: UI | E22: P1 | F22: Trang Le | G22: NOT_STARTED | H22: tests/ui/partner_010
A23: PARTNER_UI_MY_PIPELINE_002 | B23: Partner Platform | C23: Validate - Leave company name blank - Required field error is shown | D23: UI | E23: P1 | F23: Trang Le | G23: NOT_STARTED | H23: tests/ui/partner_011
A24: PARTNER_UI_MY_PIPELINE_003 | B24: Partner Platform | C24: Validate - Enter invalid domain - Domain format error is shown | D24: UI | E24: P1 | F24: Trang Le | G24: NOT_STARTED | H24: tests/ui/partner_012
A25: PARTNER_UI_MY_PIPELINE_004 | B25: Partner Platform | C25: Warn - Domain already exists - Inline active-account warning is shown | D25: UI | E25: P1 | F25: Trang Le | G25: NOT_STARTED | H25: tests/ui/partner_014
A26: PARTNER_UI_MY_PIPELINE_005 | B26: Partner Platform | C26: Submit - Existing domain with warning - Deal enters conflict queue | D26: UI | E26: P1 | F26: Trang Le | G26: NOT_STARTED | H26: tests/ui/partner_015
A27: PARTNER_UI_MY_PIPELINE_006 | B27: Partner Platform | C27: Validate - Enter contact without email - Required field error is shown | D27: UI | E27: P1 | F27: Trang Le | G27: NOT_STARTED | H27: tests/ui/partner_016
A28: PARTNER_UI_MY_PIPELINE_007 | B28: Partner Platform | C28: Validate - Enter malformed email - Email error is shown | D28: UI | E28: P1 | F28: Trang Le | G28: NOT_STARTED | H28: tests/ui/partner_017
A29: PARTNER_UI_MY_PIPELINE_008 | B29: Partner Platform | C29: Select - Choose referral deal type - Direct billing model is implied | D29: UI | E29: P1 | F29: Trang Le | G29: NOT_STARTED | H29: tests/ui/partner_020
A30: PARTNER_UI_MY_PIPELINE_009 | B30: Partner Platform | C30: Select - Choose reseller deal type - Reseller billing path is available | D30: UI | E30: P1 | F30: Trang Le | G30: NOT_STARTED | H30: tests/ui/partner_021
A31: PARTNER_UI_MY_PIPELINE_010 | B31: Partner Platform | C31: Select - Choose co-sell deal type - Co-sell option is captured | D31: UI | E31: P1 | F31: Trang Le | G31: NOT_STARTED | H31: tests/ui/partner_022
A32: PARTNER_UI_MY_PIPELINE_011 | B32: Partner Platform | C32: Confirm - Review registration summary - All entered data is displayed | D32: UI | E32: P1 | F32: Trang Le | G32: NOT_STARTED | H32: tests/ui/partner_023
A33: PARTNER_UI_MY_PIPELINE_012 | B33: Partner Platform | C33: Submit - Valid deal registration - Success response appears within 2 seconds | D33: UI | E33: P1 | F33: Trang Le | G33: NOT_STARTED | H33: tests/ui/partner_024
... A37: PARTNER_UI_MY_PIPELINE_016 | B37: Partner Platform | C37: Accept - Co-sell override proposal - Partner acceptance is recorded | D37: UI | E37: P1 | F37: Trang Le | G37: NOT_STARTED | H37: tests/ui/partner_034
A38: PARTNER_UI_MY_PIPELINE_017 | B38: Partner Platform | C38: Block - Co-sell override under or equal $100K ACV - Override option is unavailable | D38: UI | E38: P1 | F38: Trang Le | G38: NOT_STARTED
A39: PARTNER_UI_MY_PIPELINE_018 | B39: Partner Platform | C39: Require - Co-sell override above $100K ACV - Partner written agreement is required | D39: UI | E39: P1 | F39: Trang Le | G39: NOT_STARTED
A40: PARTNER_UI_MY_CLIENTS_001 | B40: Partner Platform | C40: Click - Action Required renewal CTA - Renewal registration flow opens | D40: UI | E40: P1 | F40: Trang Le | G40: NOT_STARTED | H40: tests/ui/partner_006
A41: PARTNER_UI_MY_CLIENTS_002 | B41: Partner Platform | C41: List - Open My Clients - Post-close clients are displayed | D41: UI | E41: P1 | F41: Trang Le | G41: NOT_STARTED | H41: tests/ui/partner_036
A42: PARTNER_UI_MY_CLIENTS_003 | B42: Partner Platform | C42: Open - Client health detail - ARR, renewal, usage, tickets, and CSM are visible | D42: UI | E42: P1 | F42: Trang Le | G42: NOT_STARTED | H42: tests/ui/partner_040
A43: PARTNER_UI_MY_CLIENTS_004 | B43: Partner Platform | C43: Register - Renewal deal from client detail - Renewal context is prefilled | D43: UI | E43: P1 | F43: Trang Le | G43: NOT_STARTED | H43: tests/ui/partner_041
A44: PARTNER_UI_MY_CLIENTS_005 | B44: Partner Platform | C44: Add - MSP managed client - Provisioning form is shown | D44: UI | E44: P1 | F44: Trang Le | G44: NOT_STARTED | H44: tests/ui/partner_043
A45: PARTNER_UI_MY_CLIENTS_006 | B45: Partner Platform | C45: Toggle - MSP ticket consent default - Consent is off by default | D45: UI | E45: P1 | F45: Trang Le | G45: NOT_STARTED | H45: tests/ui/partner_044
...

Sheet Execution Log
A1: Execution Log
A2: Sprint / Release | B2: Date | C2: Build Version | D2: Module | E2: TC ID | F2: Executor | G2: Result | H2: Note
A3: Sprint 1 | B3: 2026-05-20 | C3: v0.1.0-alpha | D3: Partner Platform | E3: PARTNER_UI_001 | F3: Trang Le | G3: Not Started | H3: Initial smoke run — placeholder

Sheet Test Scope
A1: TEST SCOPE
A2: Document: partner-platform-prd-v1.8 | Last updated: 2026-05-20 | Status: Living Document
A3: ✅ IN SCOPE
A4: Category | B4: Module | C4: Description | D4: Owner | E4: Status
A5: Partner Platform
A6: In Scope | B6: Partner Platform | C6: Partner portal shell: navigation, dashboard, KPI cards, tier progress, action-required list. | D6: QA Team | E6: Active
A7: In Scope | B7: Partner Platform | C7: Deal registration wizard: referral, reseller, co-sell deal types; validation, conflict detection, commission projection. | D7: QA Team | E7: Active
A8: In Scope | B8: Partner Platform | C8: Pipeline management: deal list, filters, deal detail, timeline, notes, documents, BlazeUp rep view. | D8: QA Team | E8: Active
A9: In Scope | B9: Partner Platform | C9: Client health: client list, health detail (ARR, renewal, usage, tickets), MSP managed client provisioning, consent toggle. | D9: QA Team | E9: Active
A10: In Scope | B10: Partner Platform | C10: Commissions: earned/pending/paid totals, commission trace, dispute submission, product failure waiver, payout details. | D10: QA Team | E10: Active
A11: In Scope | B11: Partner Platform | C11: Training & Resources: certifications, learning paths, marketing assets, co-branded deck, ROI calculator, sandbox reset. | D11: QA Team | E11: Active
A12: In Scope | B12: Partner Platform | C12: Team & Referral: team member invite, campaign referral link creation and analytics. | D12: QA Team | E12: Active
A13: In Scope | B13: Partner Platform | C13: SA Partner Module: partner directory, application FSM (staged approval), deal approval/conflict queues, commission config, territory, analytics, ledger approval. | D13: QA Team | E13: Active
A14: In Scope | B14: Partner Platform | C14: Backend APIs: ms-sa-partners endpoints, Kafka events, MongoDB/Redis persistence, commission engine, tenant provisioning, MSP scope guard, audit trail. | D14: QA Team | E14: Active
A15: In Scope | B15: Partner Platform | C15: Security: partner JWT separation, cross-partner isolation, MFA gates, MSP consent enforcement, SA two-eye approvals, data residency. | D15: QA Team | E15: Active
A17: 🚫 OUT OF SCOPE
A18: Category | B18: Module | C18: Description | D18: Owner | E18: Status
A19: Pack Partner
A20: Out of Scope | B20: Pack Partner | C20: Pack Partner marketplace features — only separation from Channel Partner accounts is validated. | D20: N/A | E20: Excluded
A21: Partner Platform
A22: Out of Scope | B22: Partner Platform | C22: Final Legal/Compliance decisions pending sign-off — related test cases are placeholders only. | D22: N/A | E22: Excluded
A23: Out of Scope | B23: Partner Platform | C23: Exact commission rates/window durations for NN/EN/EE stages — SA will configure values before launch; exact figures not testable yet. | D23: N/A | E23: Pending
A24: Out of Scope | B24: Partner Platform | C24: Third-party training platform vendor behavior — deferred until build-vs-buy decision is finalized. | D24: N/A | E24: Pending
A25: Other Modules
A26: Out of Scope | B26: Other Modules | C26: 9 remaining modules (CRM, etc.) — not yet assigned; will be added as requirements are provided. | D26: N/A | E26: Pending
A28: 📌 ASSUMPTIONS
A29: Category | B29: Module | C29: Description | D29: Owner | E29: Status
A30: All Modules
A31: Assumption | B31: All Modules | C31: This is a living document. New modules will be added as requirements are provided by the team. | D31: QA Team | E31: Active
A32: In Scope | B32: Partner Platform | C32: Requirement-phase automation mappings are placeholders; executable automation will be updated after requirements stabilize. | D32: QA Team | E32: Active
A33: Partner Platform
A34: Assumption | B34: Partner Platform | C34: All test statuses default to Not Started. Status logic: Fail if any = Fail; Pass if Manual = Pass and Automation = Pass/Not Started; else Not Started. | D34: QA Team | E34: Active
A35: Assumption | B35: Partner Platform | C35: Automation mapping IDs (e.g. tests/ui/partner_001) are placeholders — replace with real script paths when automation is implemented. | D35: QA Team | E35: Active
A36: Assumption | B36: Partner Platform | C36: partner.blazeup.ai (dogfood tenant) is the test target. Auth Phase 0 hooks/mocks are used for non-auth slices; live partner auth tested only after auth gate lands. | D36: Dev Team | E36: Active
A38: 🔑 ENTRY & EXIT CRITERIA
A39: Category | B39: Module | C39: Description | D39: Owner | E39: Status
A40: Partner Platform
A41: Entry Criteria | B41: Partner Platform | C41: PRD v1.8 is baselined and available to QA team. | D41: PM | E41: Active
A42: Entry Criteria | B42: Partner Platform | C42: Test environment is deployed: Partner Portal, SA Partner Module, ms-sa-partners, dogfood CRM bridge, tenant provisioning, billing, Kafka test topics. | D42: Dev Team | E42: Active
A43: Entry Criteria | B43: Partner Platform | C43: Seed data is ready: partners, deals, clients, commissions, sandbox profiles, conflict fixtures. | D43: Dev Team | E43: Active
...

Sheet Bug_Tracker
A1: Bug ID | B1: Test Case ID | C1: Test Case Name | D1: Module | E1: Feature | F1: Severity | G1: Priority | H1: Status | I1: Summary | J1: Expected | K1: Actual | L1: Evidence / Assertion | M1: Reported By | N1: Date Opened | O1: Date Closed | P1: Notes
A2: API
A3: BUG-API-001 | B3: 2060122 | C3: PARTNER_API_PARTNER_ACCOUNT_MANAGEMENT_022 | D3: Partner | E3: Certifications | F3: Major | G3: P2 | H3: Close | I3: Re-granting the same certification to the same user creates a duplicate | J3: Re-grant is idempotent (or 409) — no second active cert | K3: Returns 201 and creates a 2nd active cert | L3: AssertionError: re-granting must not duplicate active cert | M3: Trangqle | N3: 46219
A4: BUG-API-002 | B4: 2060208 | C4: PARTNER_API_DEAL_REGISTRATION_PIPELINE_008 | D4: Partner | E4: Deal Approval | F4: Major | G4: P2 | H4: Close | I4: Approving a deal does not stamp rate / rateTableVersion | J4: Approved deal exposes rate + rateTableVersion | K4: Fields not stamped/exposed | L4: AssertionError: approved deal must stamp rate + rate table version | M4: Trangqle | N4: 46219
A5: BUG-API-003 | B5: 2060221 | C5: PARTNER_API_DEAL_REGISTRATION_PIPELINE_021 | D5: Partner | E5: Deal Registration | F5: Major | G5: P2 | H5: Close | I5: Deal registration accepts a non-existent (ghost) planId | J5: Reject 4xx when planId absent (FK validation) | K5: Returns 201 registered | L5: CHECK ghost planId (verified absent) -&gt; FAIL (status=201) | M5: Trangqle | N5: 46219 | O5: 46226 | P5: Re-check is PASS
A6: BUG-API-004 | B6: 2060713 | C6: PARTNER_API_PARTNER_USERS_013 | D6: Partner | E6: Partner Users | F6: Major | G6: P2 | H6: Close | I6: Inviting a duplicate email creates a second user | J6: Reject (409) or idempotent — no duplicate user | K6: Returns 201; two users share one login | L6: AssertionError: re-inviting must not duplicate user | M6: Trangqle | N6: 46223 | O6: 46226 | P6: Re-check is PASS
A7: BUG-API-005 | B7: 2061003 | C7: PARTNER_API_AUTH_ACCESS_CONTROL_003 | D7: Partner | E7: Auth &amp; Access Control | F7: Major | G7: P2 | H7: Close | I7: Cross-partner deal access returns 400 instead of 404/403 | J7: 404 (preferred, hides existence) or 403 for cross-partner access | K7: Returns 400 (mislabels a valid request as malformed); isolation holds (no data leak) | L7: AssertionError: cross-partner access should be 404 (preferred) or 403, got 400 | M7: Trangqle | N7: 46223 | O7: 46226 | P7: Re-check is PASS
A8: BUG-API-006 | B8: 2060231 | C8: PARTNER_API_DEAL_REGISTRATION_PIPELINE_031 | D8: Partner | E8: DEAL_REGISTRATION_PIPELINE | F8: Minor | G8: P2 | H8: Close | I8: GET deal by a well-formed but non-existent id returns 400 instead of 404 | J8: 404 Not Found for a well-formed but non-existent deal id | K8: 400 Bad Request with message "Deal 000000000000000000000000 not found" (status contradicts message) | L8: test_partner_api_deal_registration_pipeline_031 [1/2]: expected 404, got 400, msg="Deal 000000000000000000000000 not found" | M8: Trangqle | N8: 46223 | O8: 46226 | P8: Re-check is PASS
A9: BUG-API-007 | B9: 2060232 | C9: PARTNER_API_DEAL_REGISTRATION_PIPELINE_032 | D9: Partner | E9: DEAL_REGISTRATION_PIPELINE | F9: Minor | G9: P2 | H9: Close | I9: lose deal on a well-formed but non-existent id returns 400 instead of 404 | J9: 404 Not Found for a well-formed but non-existent deal id | K9: 400 Bad Request with message "Deal 000000000000000000000000 not found" (status contradicts message) | L9: test_partner_api_deal_registration_pipeline_032 [2/3]: expected 404, got 400, msg="Deal 000000000000000000000000 not found" | M9: Trangqle | N9: 46223 | O9: 46226 | P9: Re-check is PASS
A10: BUG-API-008 | B10: 2060228 | C10: PARTNER_API_DEAL_REGISTRATION_PIPELINE_028 | D10: Partner | E10: DEAL_REGISTRATION_PIPELINE | F10: Minor | G10: P2 | H10: Close | I10: approve deal on a well-formed but non-existent id returns 400 instead of 404 | J10: 404 Not Found for a well-formed but non-existent deal id | K10: 400 Bad Request with message "Deal 000000000000000000000000 not found" (status contradicts message) | L10: test_partner_api_deal_registration_pipeline_028 [1/3]: expected 404, got 400, msg="Deal 000000000000000000000000 not found" | M10: Trangqle | N10: 46223 | O10: 46226 | P10: Re-check is PASS
A11: BUG-API-009 | B11: 2060229 | C11: PARTNER_API_DEAL_REGISTRATION_PIPELINE_029 | D11: Partner | E11: DEAL_REGISTRATION_PIPELINE | F11: Minor | G11: P2 | H11: Close | I11: resolve-conflict on a well-formed but non-existent id returns 400 instead of 404 | J11: 404 Not Found for a well-formed but non-existent deal id | K11: 400 Bad Request with message "Deal 000000000000000000000000 not found" (status contradicts message) | L11: test_partner_api_deal_registration_pipeline_029 [6/6]: expected 404, got 400, msg="Deal 000000000000000000000000 not found" | M11: Trangqle | N11: 46223 | O11: 46226 | P11: Re-check is PASS
A12: BUG-API-010 | B12: 2060230 | C12: PARTNER_API_DEAL_REGISTRATION_PIPELINE_030 | D12: Partner | E12: DEAL_REGISTRATION_PIPELINE | F12: Minor | G12: P2 | H12: Close | I12: extend-protection on a well-formed but non-existent id returns 400 instead of 404 | J12: 404 Not Found for a well-formed but non-existent deal id | K12: 400 Bad Request with message "Deal 000000000000000000000000 not found" (status contradicts message) | L12: test_partner_api_deal_registration_pipeline_030 [8/8]: expected 404, got 400, msg="Deal 000000000000000000000000 not found" | M12: Trangqle | N12: 46223 | O12: 46226 | P12: Re-check is PASS
A13: BUG-API-011 | B13: 2061111 | C13: PARTNER_API_DEAL_APPROVAL_QUEUE_011 | D13: Partner | E13: DEAL_APPROVAL_QUEUE | F13: Minor | G13: P2 | H13: Close | I13: reject deal on a well-formed but non-existent id returns 400 instead of 404 | J13: 404 Not Found for a well-formed but non-existent deal id | K13: 400 Bad Request with message "Deal 000000000000000000000000 not found" (status contradicts message) | L13: test_partner_api_deal_approval_queue_011 [1/3]: expected 404, got 400, msg="Deal 000000000000000000000000 not found" | M13: Trangqle | N13: 46223 | O13: 46226 | P13: Re-check is PASS
A14: BUG-API-012 | B14: 2060113 | C14: PARTNER_API_PARTNER_ACCOUNT_MANAGEMENT_013 | D14: Partner | E14: PARTNER_ACCOUNT_MANAGEMENT | F14: Minor | G14: P2 | H14: Close | I14: approve partner: well-formed but non-existent partner id returns 400 instead of 404 | J14: 404 Not Found for a well-formed but non-existent partner id | K14: 400 Bad Request with message "Partner 000000000000000000000000 not found" (status contradicts message) | L14: test_partner_api_partner_account_management_013 [1/3]: expected 404, got 400, msg="Partner 000000000000000000000000 not found" | M14: Trangqle | N14: 46223 | O14: 46300
A15: BUG-API-013 | B15: 2060114 | C15: PARTNER_API_PARTNER_ACCOUNT_MANAGEMENT_014 | D15: Partner | E15: PARTNER_ACCOUNT_MANAGEMENT | F15: Minor | G15: P2 | H15: Close | I15: deactivate partner: well-formed but non-existent partner id returns 400 instead of 404 | J15: 404 Not Found for a well-formed but non-existent partner id | K15: 400 Bad Request with message "Partner 000000000000000000000000 not found" (status contradicts message) | L15: test_partner_api_partner_account_management_014 [1/3]: expected 404, got 400, msg="Partner 000000000000000000000000 not found" | M15: Trangqle | N15: 46223 | O15: 46300
A16: BUG-API-014 | B16: 2060115 | C16: PARTNER_API_PARTNER_ACCOUNT_MANAGEMENT_015 | D16: Partner | E16: PARTNER_ACCOUNT_MANAGEMENT | F16: Minor | G16: P2 | H16: Close | I16: change-tier partner: well-formed but non-existent partner id returns 400 instead of 404 | J16: 404 Not Found for a well-formed but non-existent partner id | K16: 400 Bad Request with message "Partner 000000000000000000000000 not found" (status contradicts message) | L16: test_partner_api_partner_account_management_015 [6/6]: expected 404, got 400, msg="Partner 000000000000000000000000 not found" | M16: Trangqle | N16: 46223 | O16: 46300
A17: BUG-API-015 | B17: 2060120 | C17: PARTNER_API_PARTNER_ACCOUNT_MANAGEMENT_020 | D17: Partner | E17: PARTNER_ACCOUNT_MANAGEMENT | F17: Minor | G17: P2 | H17: Close | I17: grant-certification on a well-formed but non-existent userId returns 400 instead of 404 | J17: 404 Not Found for a well-formed but non-existent userId | K17: 400 Bad Request with message "User 000000000000000000000000 not found" (status contradicts message) | L17: test_partner_api_partner_account_management_020 [4/4]: expected 404, got 400, msg="User 000000000000000000000000 not found" | M17: Trangqle | N17: 46223 | O17: 46300 | P17: Re-check is PASS
A18: BUG-API-016 | B18: 2060714 | C18: PARTNER_API_PARTNER_USERS_014 | D18: Partner | E18: PARTNER_USERS | F18: Minor | G18: P2 | H18: Close | I18: reset-password on a well-formed but non-existent userId returns 400 instead of 404 | J18: 404 Not Found for a well-formed but non-existent userId | K18: 400 Bad Request with message "User 000000000000000000000000 not found" (status contradicts message) | L18: test_partner_api_partner_users_014 [1/2]: expected 404, got 400, msg="User 000000000000000000000000 not found" | M18: Trangqle | N18: 46223 | O18: 46300
A19: BUG-API-017 | B19: 2060414 | C19: PARTNER_API_TERRITORIES_014 | D19: Partner | E19: TERRITORIES | F19: Minor | G19: P2 | H19: Close | I19: get-territory-by-id on a well-formed but non-existent id returns 400 instead of 404 | J19: 404 Not Found for a well-formed but non-existent / already-removed territory id | K19: 400 Bad Request with message "Territory ... not found" (status contradicts message) | L19: test_partner_api_territories_014 [1/2]: expected 404, got 400, msg="Territory 000000000000000000000000 not found" | M19: Trangqle | N19: 46223 | O19: 46300
A20: BUG-API-018 | B20: 2060415 | C20: PARTNER_API_TERRITORIES_015 | D20: Partner | E20: TERRITORIES | F20: Minor | G20: P2 | H20: Close | I20: delete territory on a non-existent / already-removed id returns 400 instead of 404 | J20: 404 Not Found for a well-formed but non-existent / already-removed territory id | K20: 400 Bad Request with message "Territory ... not found" (status contradicts message) | L20: test_partner_api_territories_015 [1/3] + [3/3]: expected 404, got 400 (ghost id AND already-removed), msg="Territory ... not found" | M20: Trangqle | N20: 46223 | O20: 46300
A21: BUG-API-019 | B21: 2060512 | C21: PARTNER_API_CERTIFICATIONS_SA_012 | D21: Partner | E21: CERTIFICATIONS_SA | F21: Minor | G21: P2 | H21: Close | I21: revoke-certification not-found targets (ghost user / cert-not-held / already-revoked) return 400 instead of 404 | K21: 400 Bad Request with a "not found" message (User ... not found / Active ... certification not found) | L21: test_partner_api_certifications_sa_012: cases 2,3,5 expected 404, got 400 (msg contains not found) | M21: Trangqle | N21: 46223 | O21: 46300
A22: BUG-API-020 | B22: 2060234 | C22: PARTNER_API_DEAL_REGISTRATION_PIPELINE_034 | D22: Partner | E22: DEAL_REGISTRATION_PIPELINE | F22: Major | G22: P2 | H22: Close | I22: Win deal: WinDealDto required fields not enforced (companyWebsite/industry/adminFirstName/adminLastName) | J22: 400 when a required win-intake field is missing (per WinDealDto required list) | K22: 201 - deal is won even with all required fields missing (empty body also wins) | L22: test_partner_api_deal_registration_pipeline_034 [1-4/8]: missing companyWebsite/industry/adminFirstName/adminLastName each returned 201 (expected 400) | M22: Trangqle | N22: 46225 | O22: 46300
