Workbook

Sheet Summary
A1: TEST PLAN SUMMARY
A2: partner-platform-prd-v1.8 | Generated: 2026-05-20
A3: No. | B3: BLOCK | C3: TOTAL | D3: COMPLETED | E3: PASSED | G3: FAILED | I3: NOT STARTED | K3: IN PROGRESS | M3: BLOCKED
E4: Number | F4: Percent | G4: Number | H4: Percent | I4: Number | J4: Percent | K4: Number | L4: Percent | M4: Number | N4: Percent | O4: COMMENT | P4: OWNER
A5: 1 | B5: Partner Platform | C5: =COUNTA('Partner Platform'!C79:C1130) -> 163 | D5: =(E5+G5)/C5 -> 0.14110429 | E5: =COUNTIF('Partner Platform'!K79:K1130,"PASSED") -> 19 | F5: =E5/C5 -> 0.11656442 | G5: =COUNTIF('Partner Platform'!K79:K1130,"FAILED") -> 4 | H5: =G5/C5 -> 0.024539877 | I5: =COUNTIF('Partner Platform'!K79:K1130,"NOT_STARTED") -> 141 | J5: =I5/C5 -> 0.86503067 | K5: =COUNTIF('Partner Platform'!K79:K1130,"IN_PROGRESS") -> 0 | L5: =K5/C5 -> 0 | M5: =COUNTIF('Partner Platform'!K79:K1130,"BLOCKED") -> 0 | N5: =M5/C5 -> 0 | P5: Trang Le
B6: TOTAL | C6: =SUM(C5) -> 163 | D6: =(E6+G6)/C6 -> 0.14110429 | E6: =SUM(E5) -> 19 | F6: =E6/C6 -> 0.11656442 | G6: =SUM(G5) -> 4 | H6: =G6/C6 -> 0.024539877 | I6: =SUM(H5) -> 0.024539877 | J6: =I6/C6 -> 0.00015055139 | K6: =SUM(K5) -> 0 | L6: =K6/C6 -> 0 | M6: =SUM(M5) -> 0 | N6: =M6/C6 -> 0
A22: Status | B22: Count
A23: Pass | B23: =COUNTIF('Partner Platform'!G:G,"Pass") -> 0
A24: Fail | B24: =COUNTIF('Partner Platform'!G:G,"Fail") -> 0
A25: Not Started | B25: =COUNTIF('Partner Platform'!G:G,"Not Started") -> 0
A26: In Progress | B26: =COUNTIF('Partner Platform'!G:G,"In Progress") -> 0
A27: Type | B27: Count
A28: Type | B28: Count
A29: UI | B29: =COUNTA('Partner Platform'!B79:B94) -> 8
A30: API | B30: =COUNTA('Partner Platform'!A222:A295) -> 2
A31: Coverage | B31: Count
A32: Automation | B32: Count
A33: Automated | B33: 138
A34: Manual Only | B34: 6
A36: Priority | B36: Count
A37: P1 | B37: =COUNTIF('Partner Platform'!E:E,"P1") -> 0
A38: P2 | B38: =COUNTIF('Partner Platform'!E:E,"P2") -> 0
A39: P3 | B39: =COUNTIF('Partner Platform'!E:E,"P3") -> 0
A40: P4 | B40: =COUNTIF('Partner Platform'!E:E,"P4") -> 0

Sheet Partner Platform
A1: PARTNER PLATFORM — MODULE STATUS SUMMARY
A2: Item | B2: Description | C2: Summary | D2: Manual | E2: Automation
A3: TOTAL | B3: Total number of tests | C3: =SUM(C4:C8) -> 164 | D3: =SUM(D4:D8) -> 164 | E3: =SUM(E4:E8) -> 22
A4: PASSED | B4: Number of tests PASSED | C4: =COUNTIF('Partner Platform'!H79:H1130,"PASSED") -> 18 | D4: =COUNTIF('Partner Platform'!I79:I1130,"PASSED") -> 0 | E4: =COUNTIFS('Partner Platform'!K79:K1130,"PASSED",'Partner Platform'!J79:J1130,"YES") -> 18
A5: FAILED | B5: Number of tests FAILED | C5: =COUNTIF('Partner Platform'!H79:H1130,"FAILED") -> 4 | D5: =COUNTIF('Partner Platform'!I79:I1130,"FAILED") -> 0 | E5: =COUNTIFS('Partner Platform'!K79:K1130,"FAILED",'Partner Platform'!J79:J1130,"YES") -> 4
A6: NOT_STARTED | B6: Number of tests that have not been started | C6: =COUNTIF('Partner Platform'!H79:H1130,"NOT_STARTED") -> 126 | D6: =COUNTIF('Partner Platform'!I79:I1130,"NOT_STARTED") -> 148 | E6: =COUNTIFS('Partner Platform'!K79:K1130,"NOT_STARTED",'Partner Platform'!J79:J1130,"YES") -> 0
A7: IN_PROGRESS | B7: Number of tests currently being tested | C7: =COUNTIF('Partner Platform'!H79:H1130,"IN_PROGRESS") -> 0 | D7: =COUNTIF('Partner Platform'!I79:I1130,"IN_PROGRESS") -> 0 | E7: =COUNTIFS('Partner Platform'!K79:K1130,"IN_PROGRESS",'Partner Platform'!J79:J1130,"YES") -> 0
A8: BLOCKED | B8: Tests that could not be executed | C8: =COUNTIF('Partner Platform'!H79:H1130,"BLOCKED") -> 16 | D8: =COUNTIF('Partner Platform'!I79:I1130,"BLOCKED") -> 16 | E8: =COUNTIFS('Partner Platform'!K79:K1130,"BLOCKED",'Partner Platform'!J79:J1130,"YES") -> 0
A11: UI Test Cases
A12: Main Section | B12: Main Feature/Function | C12: Testcasename | D12: Testcase | E12: Test Type | F12: Priority | G12: Severity | H12: Status | I12: Manual Status | J12: Auto | K12: Automation Status | L12: Requirement Ref | M12: Docs Refer | N12: Bug ID | O12: Owner | P12: Note | Q12: Test Description | R12: Test Step | S12: Primary Ref
A13: Commissions | B13: Commissions & Payouts | C13: PARTNER_UI_COMMISSIONS_001 | D13: Calculate - Type estimated annual value - Commission projection updates live | E13: Functional | F13: P1 | G13: Critical | H13: =IF(J13="No",I13,IF(OR(I13="FAILED",K13="FAILED"),"FAILED",IF(OR(I13="PASSED",K13="PASSED"),"PASSED",IF(OR(I13="IN_PROGRESS",K13="IN_PROGRESS"),"IN_PROGRESS",IF(OR(I13="BLOCKED",K13="BLOCKED"),"BLOCKED","NOT_STARTED"))))) -> NOT_STARTED | I13: NOT_STARTED | J13: NO | K13: NOT_STARTED | L13: §4.4, Risk R2 | M13: partner-platform-prd-v1.8.md | O13: Trang Le | Q13: Validate the UI flow for type estimated annual value so that commission projection updates live. Scope covers the commission ledger, payout, dispute, waiver, clawback, rate, and approval behavior, authenticated partner/SA role access as applicable, visible copy/state, primary CTA behavior, and PRD coverage §4.4, Risk R2. Out of scope: unrelated modules and deep backend calculation beyond the data needed to prove this case. | R13: 1. Open the deal registration commercial/value step. 2. Select a partner tier/deal type fixture with known configured rate. 3. Type or change the estimated annual value/ACV. 4. Verify projected commission updates live with the correct currency, rate, and pending/estimated copy. 5. Confirm the projection carries through to review/confirmation and is not shown as final payout. | S13: 4.4
C14: PARTNER_UI_COMMISSIONS_002 | D14: View - Commissions page - Earned pending and paid totals are visible | E14: Functional | F14: P1 | G14: Major | H14: =IF(J14="No",I14,IF(OR(I14="FAILED",K14="FAILED"),"FAILED",IF(OR(I14="PASSED",K14="PASSED"),"PASSED",IF(OR(I14="IN_PROGRESS",K14="IN_PROGRESS"),"IN_PROGRESS",IF(OR(I14="BLOCKED",K14="BLOCKED"),"BLOCKED","NOT_STARTED"))))) -> NOT_STARTED | I14: NOT_STARTED | J14: NO | K14: NOT_STARTED | L14: §4.7 | M14: partner-platform-prd-v1.8.md | O14: Trang Le | Q14: Validate the UI flow for commissions page so that earned pending and paid totals are visible. Scope covers the commission ledger, payout, dispute, waiver, clawback, rate, and approval behavior, authenticated partner/SA role access as applicable, visible copy/state, primary CTA behavior, and PRD coverage §4.7. Out of scope: unrelated modules and deep backend calculation beyond the data needed to prove this case. | R14: 1. Navigate to Commissions with earned, pending, paid, and disputed ledger fixtures. 2. Review summary totals and ledger rows. 3. Open the target commission row if detail is required. 4. Verify deal, close, rate/version, approval, payout, clawback/waiver, and payment status fields. 5. Confirm totals reconcile to visible rows for the fixture. | S14: 4.7
C15: PARTNER_UI_COMMISSIONS_003 | D15: Trace - Commission row detail - Deal close to payment details are visible | E15: Functional | F15: P1 | G15: Major | H15: =IF(J15="No",I15,IF(OR(I15="FAILED",K15="FAILED"),"FAILED",IF(OR(I15="PASSED",K15="PASSED"),"PASSED",IF(OR(I15="IN_PROGRESS",K15="IN_PROGRESS"),"IN_PROGRESS",IF(OR(I15="BLOCKED",K15="BLOCKED"),"BLOCKED","NOT_STARTED"))))) -> NOT_STARTED | I15: NOT_STARTED | J15: NO | K15: NOT_STARTED | L15: §4.7, §5.6 | M15: partner-platform-prd-v1.8.md | O15: Trang Le | Q15: Validate the UI flow for commission row detail so that deal close to payment details are visible. Scope covers the commission ledger, payout, dispute, waiver, clawback, rate, and approval behavior, authenticated partner/SA role access as applicable, visible copy/state, primary CTA behavior, and PRD coverage §4.7, §5.6. Out of scope: unrelated modules and deep backend calculation beyond the data needed to prove this case. | R15: 1. Navigate to Commissions with earned, pending, paid, and disputed ledger fixtures. 2. Review summary totals and ledger rows. 3. Open the target commission row if detail is required. 4. Verify deal, close, rate/version, approval, payout, clawback/waiver, and payment status fields. 5. Confirm totals reconcile to visible rows for the fixture. | S15: 4.7
C16: PARTNER_UI_COMMISSIONS_004 | D16: Submit - Commission dispute - Dispute is created from one text field | E16: Functional | F16: P1 | G16: Major | H16: =IF(J16="No",I16,IF(OR(I16="FAILED",K16="FAILED"),"FAILED",IF(OR(I16="PASSED",K16="PASSED"),"PASSED",IF(OR(I16="IN_PROGRESS",K16="IN_PROGRESS"),"IN_PROGRESS",IF(OR(I16="BLOCKED",K16="BLOCKED"),"BLOCKED","NOT_STARTED"))))) -> NOT_STARTED | I16: NOT_STARTED | J16: NO | K16: NOT_STARTED | L16: §4.7 | M16: partner-platform-prd-v1.8.md | O16: Trang Le | Q16: Validate the UI flow for commission dispute so that dispute is created from one text field. Scope covers the commission ledger, payout, dispute, waiver, clawback, rate, and approval behavior, authenticated partner/SA role access as applicable, visible copy/state, primary CTA behavior, and PRD coverage §4.7. Out of scope: unrelated modules and deep backend calculation beyond the data needed to prove this case. | R16: 1. Open Commissions using a fixture eligible for the requested action. 2. Start the action: Commission dispute. 3. Enter the minimum required information or evidence/payment fields. 4. Submit and verify validation, confirmation, and new status/history entry. 5. Confirm dispute is created from one text field and sensitive details are masked or region-appropriate where applicable. | S16: 4.7
C17: PARTNER_UI_COMMISSIONS_005 | D17: Submit - Product failure waiver - Evidence can be linked and request submitted | E17: Functional | F17: P1 | G17: Critical | H17: =IF(J17="No",I17,IF(OR(I17="FAILED",K17="FAILED"),"FAILED",IF(OR(I17="PASSED",K17="PASSED"),"PASSED",IF(OR(I17="IN_PROGRESS",K17="IN_PROGRESS"),"IN_PROGRESS",IF(OR(I17="BLOCKED",K17="BLOCKED"),"BLOCKED","NOT_STARTED"))))) -> NOT_STARTED | I17: NOT_STARTED | J17: NO | K17: NOT_STARTED | L17: §4.7, §5.3 | M17: partner-platform-prd-v1.8.md | O17: Trang Le | Q17: Validate the UI flow for product failure waiver so that evidence can be linked and request submitted. Scope covers the commission ledger, payout, dispute, waiver, clawback, rate, and approval behavior, authenticated partner/SA role access as applicable, visible copy/state, primary CTA behavior, and PRD coverage §4.7, §5.3. Out of scope: unrelated modules and deep backend calculation beyond the data needed to prove this case. | R17: 1. Open Commissions using a fixture eligible for the requested action. 2. Start the action: Product failure waiver. 3. Enter the minimum required information or evidence/payment fields. 4. Submit and verify validation, confirmation, and new status/history entry. 5. Confirm evidence can be linked and request submitted and sensitive details are masked or region-appropriate where applicable. | S17: 4.7
C18: PARTNER_UI_COMMISSIONS_006 | D18: Approve - Commission payout over $10K - Two-eye approval is enforced | E18: Security | F18: P1 | G18: Critical | H18: =IF(J18="No",I18,IF(OR(I18="FAILED",K18="FAILED"),"FAILED",IF(OR(I18="PASSED",K18="PASSED"),"PASSED",IF(OR(I18="IN_PROGRESS",K18="IN_PROGRESS"),"IN_PROGRESS",IF(OR(I18="BLOCKED",K18="BLOCKED"),"BLOCKED","NOT_STARTED"))))) -> NOT_STARTED | I18: NOT_STARTED | J18: NO | K18: NOT_STARTED | L18: §5.6, §7.5 | M18: partner-platform-prd-v1.8.md | O18: Trang Le | Q18: Validate the UI flow for commission payout over $10k so that two-eye approval is enforced. Scope covers the commission ledger, payout, dispute, waiver, clawback, rate, and approval behavior, authenticated partner/SA role access as applicable, visible copy/state, primary CTA behavior, and PRD coverage §5.6, §7.5. Out of scope: unrelated modules and deep backend calculation beyond the data needed to prove this case. | R18: 1. Log in as an active channel partner user with fixture data that supports this scenario. 2. Open /commissions and confirm the expected partner/SA shell is loaded. 3. Perform the action: approve / Commission payout over $10K. 4. Verify that two-eye approval is enforced and that no unrelated page state regresses. 5. Capture any validation message, status badge, audit indicator, or navigation result required by §5.6, §7.5. | S18: 5.6
C19: PARTNER_UI_COMMISSIONS_007 | D19: Display - Clawback notification - Policy terms and product-failure waiver path are visible | E19: Functional | F19: P1 | G19: Major | H19: =IF(J19="No",I19,IF(OR(I19="FAILED",K19="FAILED"),"FAILED",IF(OR(I19="PASSED",K19="PASSED"),"PASSED",IF(OR(I19="IN_PROGRESS",K19="IN_PROGRESS"),"IN_PROGRESS",IF(OR(I19="BLOCKED",K19="BLOCKED"),"BLOCKED","NOT_STARTED"))))) -> NOT_STARTED | I19: NOT_STARTED | J19: NO | K19: NOT_STARTED | L19: §4.7, §5.3 | M19: partner-platform-prd-v1.8.md | O19: Trang Le | P19: Terms must be shown at approval/notification, not as a surprise. | Q19: Validate the UI flow for clawback notification so that policy terms and product-failure waiver path are visible. Scope covers the commission ledger, payout, dispute, waiver, clawback, rate, and approval behavior, authenticated partner/SA role access as applicable, visible copy/state, primary CTA behavior, and PRD coverage §4.7, §5.3. Out of scope: unrelated modules and deep backend calculation beyond the data needed to prove this case. | R19: 1. Open Commissions using a fixture eligible for the requested action. 2. Start the action: Clawback notification. 3. Enter the minimum required information or evidence/payment fields. 4. Submit and verify validation, confirmation, and new status/history entry. 5. Confirm policy terms and product-failure waiver path are visible and sensitive details are masked or region-appropriate where applicable. | S19: 4.7
C20: PARTNER_UI_COMMISSIONS_008 | D20: Ask - Blazey commission question - Contextual answer is returned | E20: Functional | F20: P2 | G20: Major | H20: =IF(J20="No",I20,IF(OR(I20="FAILED",K20="FAILED"),"FAILED",IF(OR(I20="PASSED",K20="PASSED"),"PASSED",IF(OR(I20="IN_PROGRESS",K20="IN_PROGRESS"),"IN_PROGRESS",IF(OR(I20="BLOCKED",K20="BLOCKED"),"BLOCKED","NOT_STARTED"))))) -> NOT_STARTED | I20: NOT_STARTED | J20: NO | K20: NOT_STARTED | L20: §4.3, §10 | M20: partner-platform-prd-v1.8.md | O20: Trang Le | P20: Blazey assistant requirement; §10 is effort estimate only. | Q20: Validate the UI flow for blazey commission question so that contextual answer is returned. Scope covers the commission ledger, payout, dispute, waiver, clawback, rate, and approval behavior, authenticated partner/SA role access as applicable, visible copy/state, primary CTA behavior, and PRD coverage §4.3, §10. Out of scope: unrelated modules and deep backend calculation beyond the data needed to prove this case. | R20: 1. Open Dashboard or Commissions page where Blazey assistant is available. 2. Ask a commission-related question using the partner fixture context. 3. Verify the answer references the correct deal/tier/rate context without exposing other partners. 4. Confirm the response includes actionable next step or explanation, not a generic fallback. 5. Check that assistant loading/error states remain usable. | S20: 46305
C21: PARTNER_UI_COMMISSIONS_009 | D21: Edit - Payout details by region - Correct payment methods are available | E21: Security | F21: P2 | G21: Major | H21: =IF(J21="No",I21,IF(OR(I21="FAILED",K21="FAILED"),"FAILED",IF(OR(I21="PASSED",K21="PASSED"),"PASSED",IF(OR(I21="IN_PROGRESS",K21="IN_PROGRESS"),"IN_PROGRESS",IF(OR(I21="BLOCKED",K21="BLOCKED"),"BLOCKED","NOT_STARTED"))))) -> NOT_STARTED | I21: NOT_STARTED | J21: NO | K21: NOT_STARTED | L21: §4.7 | M21: partner-platform-prd-v1.8.md | O21: Trang Le | P21: SWIFT, ACH, NEFT/IMPS, Vietnam bank transfer. | Q21: Validate the UI flow for payout details by region so that correct payment methods are available. Scope covers the commission ledger, payout, dispute, waiver, clawback, rate, and approval behavior, authenticated partner/SA role access as applicable, visible copy/state, primary CTA behavior, and PRD coverage §4.7. Out of scope: unrelated modules and deep backend calculation beyond the data needed to prove this case. | R21: 1. Open Commissions using a fixture eligible for the requested action. 2. Start the action: Payout details by region. 3. Enter the minimum required information or evidence/payment fields. 4. Submit and verify validation, confirmation, and new status/history entry. 5. Confirm correct payment methods are available and sensitive details are masked or region-appropriate where applicable. | S21: 4.7
B22: Commission Display | C22: PARTNER_UI_COMMISSIONS_010 | D22: Display - Reseller deal commission - Reseller rate shown, not referral rate | E22: Functional | F22: P1 | G22: Major | H22: =IF(J22="No",I22,IF(OR(I22="FAILED",K22="FAILED"),"FAILED",IF(OR(I22="PASSED",K22="PASSED"),"PASSED",IF(OR(I22="IN_PROGRESS",K22="IN_PROGRESS"),"IN_PROGRESS",IF(OR(I22="BLOCKED",K22="BLOCKED"),"BLOCKED","NOT_STARTED"))))) -> NOT_STARTED | I22: NOT_STARTED | J22: NO | K22: NOT_STARTED | L22: §3 Scenario B, §4.7, §5.3 | M22: partner-platform-prd-v1.8.md | O22: Trang Le | P22: Reseller commission rate differs from Pure Referral rate — must not show referral rate | Q22: Validate the UI flow for reseller deal commission display so that reseller rate is shown and referral rate is not applied. Scope covers the Commissions & Payouts page, deal-level commission breakdown, rate label, and PRD coverage §3 Scenario B, §4.7, §5.3. Out of scope: payout processing and ledger export. | R22: 1. Log in as reseller partner with a Won reseller deal. 2. Navigate to Commissions & Payouts. 3. Locate the commission entry for the reseller deal. 4. Verify commission rate shown is the configured reseller rate (not referral/co-sell rate). 5. Confirm rate label clearly identifies it as reseller commission. 6. Verify referral rate is not applied to this deal. | S22: 46207
B23: Invoice & Billing | C23: PARTNER_UI_COMMISSIONS_011 | D23: Invoice - Reseller deal close - Invoice generated for partner not end-client | E23: Functional | F23: P1 | G23: Critical | H23: =IF(J23="No",I23,IF(OR(I23="FAILED",K23="FAILED"),"FAILED",IF(OR(I23="PASSED",K23="PASSED"),"PASSED",IF(OR(I23="IN_PROGRESS",K23="IN_PROGRESS"),"IN_PROGRESS",IF(OR(I23="BLOCKED",K23="BLOCKED"),"BLOCKED","NOT_STARTED"))))) -> NOT_STARTED | I23: NOT_STARTED | J23: NO | K23: NOT_STARTED | L23: §3 Scenario B, §5.3 | M23: partner-platform-prd-v1.8.md | O23: Trang Le | P23: Locked decision: BlazeUp invoices the PARTNER, never the end-client, for reseller deals | Q23: Validate the UI flow for reseller deal invoice so that invoice is generated for partner not end-client. Scope covers the Commissions & Payouts page, invoice/billing section, invoice recipient display, and PRD coverage §3 Scenario B, §5.3. Out of scope: actual payment processing. | R23: 1. Log in as reseller partner with a Won reseller deal that has passed commission processing. 2. Navigate to Commissions & Payouts. 3. Locate the invoice or billing record for the reseller deal. 4. Verify invoice recipient is the partner entity, not the end-client. 5. Confirm no invoice referencing the end-client name or billing details is visible. 6. Verify invoice amount matches the partner's reseller rate on the deal value. | S23: 3-B
A24: Dashboard | B24: Home KPIs & Actions | C24: PARTNER_UI_DASHBOARD_001 | D24: View - Partner shell loads for channel partner - Dashboard is displayed | E24: Functional | F24: P1 | G24: Critical | H24: =IF(J24="No",I24,IF(OR(I24="FAILED",K24="FAILED"),"FAILED",IF(OR(I24="PASSED",K24="PASSED"),"PASSED",IF(OR(I24="IN_PROGRESS",K24="IN_PROGRESS"),"IN_PROGRESS",IF(OR(I24="BLOCKED",K24="BLOCKED"),"BLOCKED","NOT_STARTED"))))) -> NOT_STARTED | I24: NOT_STARTED | J24: NO | K24: NOT_STARTED | L24: §4.1, §4.2 | M24: partner-platform-prd-v1.8.md | O24: Trang Le | P24: Verify partner.blazeup.ai shell, navigation, and federated dashboard. | Q24: Validate the UI flow for partner shell loads for channel partner so that dashboard is displayed. Scope covers the partner dashboard KPI, action-required, pipeline snapshot, and tier-progress experience, authenticated partner/SA role access as applicable, visible copy/state, primary CTA behavior, and PRD coverage §4.1, §4.2. Out of scope: unrelated modules and deep backend calculation beyond the data needed to prove this case. | R24: 1. Log in as an active channel partner user. 2. Navigate to partner portal root `/`. 3. Confirm the Partner shell, brand, demo/banner area, help/profile controls, and navigation render. 4. Verify Dashboard is the active page and no tenant/SA-only navigation is exposed. 5. Confirm seeded dashboard content is visible without loading or authorization errors. | S24: 46057
C25: PARTNER_UI_DASHBOARD_002 | D25: Render - Dashboard KPI cards available - Actionable metrics are visible | E25: Functional | F25: P1 | G25: Major | H25: =IF(J25="No",I25,IF(OR(I25="FAILED",K25="FAILED"),"FAILED",IF(OR(I25="PASSED",K25="PASSED"),"PASSED",IF(OR(I25="IN_PROGRESS",K25="IN_PROGRESS"),"IN_PROGRESS",IF(OR(I25="BLOCKED",K25="BLOCKED"),"BLOCKED","NOT_STARTED"))))) -> NOT_STARTED | I25: NOT_STARTED | J25: NO | K25: NOT_STARTED | L25: §4.3 | M25: partner-platform-prd-v1.8.md | O25: Trang Le | P25: Pipeline, commission, active clients, and tier progress cards. | Q25: Validate the UI flow for dashboard kpi cards available so that actionable metrics are visible. Scope covers the partner dashboard KPI, action-required, pipeline snapshot, and tier-progress experience, authenticated partner/SA role access as applicable, visible copy/state, primary CTA behavior, and PRD coverage §4.3. Out of scope: unrelated modules and deep backend calculation beyond the data needed to prove this case. | R25: 1. Open the Dashboard as a partner with seeded pipeline, commission, client, and tier data. 2. Locate the KPI cards for Pipeline, Commission, Active Clients, and Tier. 3. Verify values, sublabels, icons/status styling, and clickable affordances are visible. 4. Compare displayed values to the fixture dataset used for the test. 5. Confirm loading skeletons are gone and no KPI is blank or duplicated. | S25: 4.3
C26: PARTNER_UI_DASHBOARD_003 | D26: Render - Tier progress exists on dashboard - Progress to next tier is visible | E26: Functional | F26: P1 | G26: Major | H26: =IF(J26="No",I26,IF(OR(I26="FAILED",K26="FAILED"),"FAILED",IF(OR(I26="PASSED",K26="PASSED"),"PASSED",IF(OR(I26="IN_PROGRESS",K26="IN_PROGRESS"),"IN_PROGRESS",IF(OR(I26="BLOCKED",K26="BLOCKED"),"BLOCKED","NOT_STARTED"))))) -> NOT_STARTED | I26: NOT_STARTED | J26: NO | K26: NOT_STARTED | L26: §2.1, §4.3 | M26: partner-platform-prd-v1.8.md | O26: Trang Le | Q26: Validate the UI flow for tier progress exists on dashboard so that progress to next tier is visible. Scope covers the partner dashboard KPI, action-required, pipeline snapshot, and tier-progress experience, authenticated partner/SA role access as applicable, visible copy/state, primary CTA behavior, and PRD coverage §2.1, §4.3. Out of scope: unrelated modules and deep backend calculation beyond the data needed to prove this case. | R26: 1. Open Dashboard using a partner fixture with current tier, T12M ARR, and next-tier threshold. 2. Locate the Tier Progress component. 3. Verify current tier, threshold target, progress bar, current ARR, and remaining delta are shown. 4. Change fixture or use a partner near threshold if supported and refresh. 5. Confirm progress and next-tier copy follow PRD tier rules and remain readable. | S26: 4.3
C27: PARTNER_UI_DASHBOARD_004 | D27: Render - Action Required list has pending tasks - Partner sees next actions | E27: Functional | F27: P1 | G27: Major | H27: =IF(J27="No",I27,IF(OR(I27="FAILED",K27="FAILED"),"FAILED",IF(OR(I27="PASSED",K27="PASSED"),"PASSED",IF(OR(I27="IN_PROGRESS",K27="IN_PROGRESS"),"IN_PROGRESS",IF(OR(I27="BLOCKED",K27="BLOCKED"),"BLOCKED","NOT_STARTED"))))) -> NOT_STARTED | I27: NOT_STARTED | J27: NO | K27: NOT_STARTED | L27: §4.3 | M27: partner-platform-prd-v1.8.md | O27: Trang Le | Q27: Validate the UI flow for action required list has pending tasks so that partner sees next actions. Scope covers the partner dashboard KPI, action-required, pipeline snapshot, and tier-progress experience, authenticated partner/SA role access as applicable, visible copy/state, primary CTA behavior, and PRD coverage §4.3. Out of scope: unrelated modules and deep backend calculation beyond the data needed to prove this case. | R27: 1. Open Dashboard with fixture data containing at least one renewal/action item. 2. Locate the Action Required section. 3. Verify each item shows clear context, client/deal name, urgency/status, and the correct CTA. 4. Click the relevant CTA when applicable. 5. Confirm navigation or detail state matches the item type and no stale action remains visible. | S27: 4.3
C28: PARTNER_UI_DASHBOARD_005 | D28: Calculate - Tier qualification dashboard - T12M ARR threshold and next-tier delta are visible | E28: Functional | F28: P1 | G28: Major | H28: =IF(J28="No",I28,IF(OR(I28="FAILED",K28="FAILED"),"FAILED",IF(OR(I28="PASSED",K28="PASSED"),"PASSED",IF(OR(I28="IN_PROGRESS",K28="IN_PROGRESS"),"IN_PROGRESS",IF(OR(I28="BLOCKED",K28="BLOCKED"),"BLOCKED","NOT_STARTED"))))) -> NOT_STARTED | I28: NOT_STARTED | J28: NO | K28: NOT_STARTED | L28: §2.1, §4.3 | M28: partner-platform-prd-v1.8.md | O28: Trang Le | P28: Requirement-phase case; automation mapping later. | Q28: Validate the UI flow for tier qualification dashboard so that t12m arr threshold and next-tier delta are visible. Scope covers the partner dashboard KPI, action-required, pipeline snapshot, and tier-progress experience, authenticated partner/SA role access as applicable, visible copy/state, primary CTA behavior, and PRD coverage §2.1, §4.3. Out of scope: unrelated modules and deep backend calculation beyond the data needed to prove this case. | R28: 1. Open Dashboard using a partner fixture with current tier, T12M ARR, and next-tier threshold. 2. Locate the Tier Progress component. 3. Verify current tier, threshold target, progress bar, current ARR, and remaining delta are shown. 4. Change fixture or use a partner near threshold if supported and refresh. 5. Confirm progress and next-tier copy follow PRD tier rules and remain readable. | S28: 4.3
B29: Tier Progress | C29: PARTNER_UI_DASHBOARD_006 | D29: Warn - Tier downgrade pending - 30-day notice and grace quarter are displayed | E29: Functional | F29: P1 | G29: Major | H29: =IF(J29="No",I29,IF(OR(I29="FAILED",K29="FAILED"),"FAILED",IF(OR(I29="PASSED",K29="PASSED"),"PASSED",IF(OR(I29="IN_PROGRESS",K29="IN_PROGRESS"),"IN_PROGRESS",IF(OR(I29="BLOCKED",K29="BLOCKED"),"BLOCKED","NOT_STARTED"))))) -> NOT_STARTED | I29: NOT_STARTED | J29: NO | K29: NOT_STARTED | L29: §2.1, §5.5 | M29: partner-platform-prd-v1.8.md | O29: Trang Le | P29: Covers downgrade psychology and grace-quarter rule. | Q29: Validate the UI flow for tier downgrade pending so that 30-day notice and grace quarter are displayed. Scope covers the partner dashboard KPI, action-required, pipeline snapshot, and tier-progress experience, authenticated partner/SA role access as applicable, visible copy/state, primary CTA behavior, and PRD coverage §2.1, §5.5. Out of scope: unrelated modules and deep backend calculation beyond the data needed to prove this case. | R29: 1. Log in as an active channel partner user with fixture data that supports this scenario. 2. Open / and confirm the expected partner/SA shell is loaded. 3. Perform the action: warn / Tier downgrade pending. 4. Verify that 30-day notice and grace quarter are displayed and that no unrelated page state regresses. 5. Capture any validation message, status badge, audit indicator, or navigation result required by §2.1, §5.5. | S29: 5.5
B30: Home KPIs & Actions | C30: PARTNER_UI_DASHBOARD_007 | D30: Validate - Dashboard hides vanity metrics - Only actionable/clickable values are shown | E30: Negative | F30: P3 | G30: Minor | H30: =IF(J30="No",I30,IF(OR(I30="FAILED",K30="FAILED"),"FAILED",IF(OR(I30="PASSED",K30="PASSED"),"PASSED",IF(OR(I30="IN_PROGRESS",K30="IN_PROGRESS"),"IN_PROGRESS",IF(OR(I30="BLOCKED",K30="BLOCKED"),"BLOCKED","NOT_STARTED"))))) -> NOT_STARTED | I30: NOT_STARTED | J30: NO | K30: NOT_STARTED | L30: §4.3 | M30: partner-platform-prd-v1.8.md | O30: Trang Le | Q30: Validate the UI flow for dashboard hides vanity metrics so that only actionable/clickable values are shown. Scope covers the partner dashboard KPI, action-required, pipeline snapshot, and tier-progress experience, authenticated partner/SA role access as applicable, visible copy/state, primary CTA behavior, and PRD coverage §4.3. Out of scope: unrelated modules and deep backend calculation beyond the data needed to prove this case. | R30: 1. Open Dashboard with standard partner fixture data. 2. Review all visible metrics and cards. 3. Confirm each displayed value is actionable, navigable, or decision-supporting per PRD. 4. Verify non-actionable vanity metrics are absent from the first dashboard view. 5. Confirm page hierarchy still highlights action items, tier progress, and pipeline snapshot. | S30: 4.3
B31: Blazey AI Assistant | C31: PARTNER_UI_DASHBOARD_008 | D31: Ask - Blazey deal status question on dashboard - Current deal stage and assigned rep contact are returned | E31: Functional | F31: P2 | G31: Major | H31: =IF(J31="No",I31,IF(OR(I31="FAILED",K31="FAILED"),"FAILED",IF(OR(I31="PASSED",K31="PASSED"),"PASSED",IF(OR(I31="IN_PROGRESS",K31="IN_PROGRESS"),"IN_PROGRESS",IF(OR(I31="BLOCKED",K31="BLOCKED"),"BLOCKED","NOT_STARTED"))))) -> NOT_STARTED | I31: NOT_STARTED | J31: NO | K31: NOT_STARTED | L31: §4.3, §10.10 | M31: partner-platform-prd-v1.8.md | O31: Trang Le | P31: [FIX ADDED 2026-05-27] §10.10 Blazey "deal status" tool not covered — added TC | Q31: Validate the Blazey AI assistant on the dashboard correctly handles deal status queries so that current deal stage and assigned rep contact are returned. | R31: 1. Log in as an active channel partner. 2. On the dashboard, open the Blazey AI assistant widget. 3. Type a deal status query e.g. "What is the status of my deal with Acme Corp?". 4. Verify the response includes: current deal stage, next action, and BlazeUp rep contact. 5. Confirm the response is scoped to the logged-in partner deals only. | S31: 4.3
C32: PARTNER_UI_DASHBOARD_009 | D32: Ask - Blazey tier projection question on dashboard - ARR needed and timeline to next tier are displayed | E32: Functional | F32: P2 | G32: Major | H32: =IF(J32="No",I32,IF(OR(I32="FAILED",K32="FAILED"),"FAILED",IF(OR(I32="PASSED",K32="PASSED"),"PASSED",IF(OR(I32="IN_PROGRESS",K32="IN_PROGRESS"),"IN_PROGRESS",IF(OR(I32="BLOCKED",K32="BLOCKED"),"BLOCKED","NOT_STARTED"))))) -> NOT_STARTED | I32: NOT_STARTED | J32: NO | K32: NOT_STARTED | L32: §4.3, §10.10 | M32: partner-platform-prd-v1.8.md | O32: Trang Le | P32: [FIX ADDED 2026-05-27] §10.10 Blazey "tier projection" tool not covered — added TC | Q32: Validate the Blazey AI assistant on the dashboard correctly handles tier projection queries so that ARR needed and timeline to next tier are displayed. | R32: 1. Log in as an active channel partner. 2. On the dashboard, open the Blazey AI assistant widget. 3. Type a tier projection query e.g. "How much more ARR do I need to reach Premier?". 4. Verify the response includes: current tier, T12M ARR, ARR gap to next tier, and estimated timeline. 5. Confirm figures match the tier progress bar data displayed on dashboard. | S32: 4.3
A33: My Clients | B33: Client Health & MSP | C33: PARTNER_UI_MY_CLIENTS_001 | D33: Click - Action Required renewal CTA - Renewal registration flow opens | E33: Functional | F33: P1 | G33: Major | H33: =IF(J33="No",I33,IF(OR(I33="FAILED",K33="FAILED"),"FAILED",IF(OR(I33="PASSED",K33="PASSED"),"PASSED",IF(OR(I33="IN_PROGRESS",K33="IN_PROGRESS"),"IN_PROGRESS",IF(OR(I33="BLOCKED",K33="BLOCKED"),"BLOCKED","NOT_STARTED"))))) -> NOT_STARTED | I33: NOT_STARTED | J33: NO | K33: NOT_STARTED | L33: §4.3, §4.6 | M33: partner-platform-prd-v1.8.md | O33: Trang Le | Q33: Validate the UI flow for action required renewal cta so that renewal registration flow opens. Scope covers the post-close client list, client health detail, renewal actions, and MSP consent/access behavior, authenticated partner/SA role access as applicable, visible copy/state, primary CTA behavior, and PRD coverage §4.3, §4.6. Out of scope: unrelated modules and deep backend calculation beyond the data needed to prove this case. | R33: 1. Open Dashboard as a partner with a fixture containing a client renewal action item (e.g. Meridian Ltd renewal in 18 days). 2. Locate the Action Required section and confirm the renewal item shows client name, renewal date, and a Register renewal deal CTA. 3. Click the Register renewal deal CTA on the renewal action item. 4. Verify the deal registration wizard opens in renewal/expansion context with the client name and tenant reference prefilled. 5. Confirm the registration form does not require re-entering company details already known from the existing client record. | S33: 4.6
C34: PARTNER_UI_MY_CLIENTS_002 | D34: List - Open My Clients - Post-close clients are displayed | E34: Functional | F34: P1 | G34: Major | H34: =IF(J34="No",I34,IF(OR(I34="FAILED",K34="FAILED"),"FAILED",IF(OR(I34="PASSED",K34="PASSED"),"PASSED",IF(OR(I34="IN_PROGRESS",K34="IN_PROGRESS"),"IN_PROGRESS",IF(OR(I34="BLOCKED",K34="BLOCKED"),"BLOCKED","NOT_STARTED"))))) -> NOT_STARTED | I34: NOT_STARTED | J34: NO | K34: NOT_STARTED | L34: §4.6 | M34: partner-platform-prd-v1.8.md | O34: Trang Le | Q34: Validate the UI flow for open my clients so that post-close clients are displayed. Scope covers the post-close client list, client health detail, renewal actions, and MSP consent/access behavior, authenticated partner/SA role access as applicable, visible copy/state, primary CTA behavior, and PRD coverage §4.6. Out of scope: unrelated modules and deep backend calculation beyond the data needed to prove this case. | R34: 1. Navigate to My Clients with active client fixtures including healthy, at-risk, and renewing clients. 2. Apply the action/filter/search: Open My Clients. 3. Verify client rows show name, ARR, health, renewal date, and modules. 4. Confirm post-close clients are displayed and counts/tabs match the fixture. 5. Clear filters and confirm the complete client list returns. | S34: 4.6
C35: PARTNER_UI_MY_CLIENTS_003 | D35: Open - Client health detail - ARR, renewal, usage, tickets, and CSM are visible | E35: Functional | F35: P1 | G35: Critical | H35: =IF(J35="No",I35,IF(OR(I35="FAILED",K35="FAILED"),"FAILED",IF(OR(I35="PASSED",K35="PASSED"),"PASSED",IF(OR(I35="IN_PROGRESS",K35="IN_PROGRESS"),"IN_PROGRESS",IF(OR(I35="BLOCKED",K35="BLOCKED"),"BLOCKED","NOT_STARTED"))))) -> NOT_STARTED | I35: NOT_STARTED | J35: NO | K35: NOT_STARTED | L35: §1.3, §4.6 | M35: partner-platform-prd-v1.8.md | O35: Trang Le | Q35: Validate the UI flow for client health detail so that arr, renewal, usage, tickets, and csm are visible. Scope covers the post-close client list, client health detail, renewal actions, and MSP consent/access behavior, authenticated partner/SA role access as applicable, visible copy/state, primary CTA behavior, and PRD coverage §1.3, §4.6. Out of scope: unrelated modules and deep backend calculation beyond the data needed to prove this case. | R35: 1. Open My Clients and select a seeded client such as Meridian Ltd. 2. Navigate to the Client Health Detail page. 3. Verify ARR, renewal, adoption/usage, module health, ticket summary, and CSM/owner context are visible. 4. Confirm Blazey insight or renewal recommendation appears when the fixture is at risk. 5. Verify CTA behavior does not expose restricted client data. | S35: 4.6
C36: PARTNER_UI_MY_CLIENTS_004 | D36: Register - Renewal deal from client detail - Renewal context is prefilled | E36: Functional | F36: P1 | G36: Major | H36: =IF(J36="No",I36,IF(OR(I36="FAILED",K36="FAILED"),"FAILED",IF(OR(I36="PASSED",K36="PASSED"),"PASSED",IF(OR(I36="IN_PROGRESS",K36="IN_PROGRESS"),"IN_PROGRESS",IF(OR(I36="BLOCKED",K36="BLOCKED"),"BLOCKED","NOT_STARTED"))))) -> NOT_STARTED | I36: NOT_STARTED | J36: NO | K36: NOT_STARTED | L36: §3 Scenario F, §4.6 | M36: partner-platform-prd-v1.8.md | O36: Trang Le | Q36: Validate the UI flow for renewal deal from client detail so that renewal context is prefilled. Scope covers the post-close client list, client health detail, renewal actions, and MSP consent/access behavior, authenticated partner/SA role access as applicable, visible copy/state, primary CTA behavior, and PRD coverage §3 Scenario F, §4.6. Out of scope: unrelated modules and deep backend calculation beyond the data needed to prove this case. | R36: 1. Open Dashboard or Client Health Detail with Meridian Ltd renewal fixture. 2. Click the Register renewal deal CTA. 3. Confirm the deal-registration flow opens in renewal/expansion context. 4. Verify client name, tenant/client reference, renewal date, and existing module context are prefilled. 5. Confirm the user can continue without re-entering unrelated new-logo data. | S36: 4.6
C37: PARTNER_UI_MY_CLIENTS_005 | D37: Add - MSP managed client - Provisioning form is shown | E37: Functional | F37: P1 | G37: Critical | H37: =IF(J37="No",I37,IF(OR(I37="FAILED",K37="FAILED"),"FAILED",IF(OR(I37="PASSED",K37="PASSED"),"PASSED",IF(OR(I37="IN_PROGRESS",K37="IN_PROGRESS"),"IN_PROGRESS",IF(OR(I37="BLOCKED",K37="BLOCKED"),"BLOCKED","NOT_STARTED"))))) -> NOT_STARTED | I37: NOT_STARTED | J37: NO | K37: NOT_STARTED | L37: §3 Scenario G, §7.3 | M37: partner-platform-prd-v1.8.md | O37: Trang Le | Q37: Validate the UI flow for msp managed client so that provisioning form is shown. Scope covers the post-close client list, client health detail, renewal actions, and MSP consent/access behavior, authenticated partner/SA role access as applicable, visible copy/state, primary CTA behavior, and PRD coverage §3 Scenario G, §7.3. Out of scope: unrelated modules and deep backend calculation beyond the data needed to prove this case. | R37: 1. Log in as an MSP partner with managed-client fixtures. 2. Open My Clients or client provisioning flow for: MSP managed client. 3. Verify ticket-content consent is off by default unless explicitly granted. 4. Confirm counts/severity are visible but body/content is hidden without consent. 5. Complete the action and verify provisioning form is shown with audit-friendly consent state. | S37: 3-G
C38: PARTNER_UI_MY_CLIENTS_006 | D38: Toggle - MSP ticket consent default - Consent is off by default | E38: Security | F38: P1 | G38: Major | H38: =IF(J38="No",I38,IF(OR(I38="FAILED",K38="FAILED"),"FAILED",IF(OR(I38="PASSED",K38="PASSED"),"PASSED",IF(OR(I38="IN_PROGRESS",K38="IN_PROGRESS"),"IN_PROGRESS",IF(OR(I38="BLOCKED",K38="BLOCKED"),"BLOCKED","NOT_STARTED"))))) -> NOT_STARTED | I38: NOT_STARTED | J38: NO | K38: NOT_STARTED | L38: §3 Scenario G, §7.3, §9.2 | M38: partner-platform-prd-v1.8.md | O38: Trang Le | Q38: Validate the UI flow for msp ticket consent default so that consent is off by default. Scope covers the post-close client list, client health detail, renewal actions, and MSP consent/access behavior, authenticated partner/SA role access as applicable, visible copy/state, primary CTA behavior, and PRD coverage §3 Scenario G, §7.3, §9.2. Out of scope: unrelated modules and deep backend calculation beyond the data needed to prove this case. | R38: 1. Log in as an MSP partner with managed-client fixtures. 2. Open My Clients or client provisioning flow for: MSP ticket consent default. 3. Verify ticket-content consent is off by default unless explicitly granted. 4. Confirm counts/severity are visible but body/content is hidden without consent. 5. Complete the action and verify consent is off by default with audit-friendly consent state. | S38: 3-G
C39: PARTNER_UI_MY_CLIENTS_007 | D39: Filter - Renewal This Quarter - Only qualifying clients are shown | E39: Functional | F39: P2 | G39: Major | H39: =IF(J39="No",I39,IF(OR(I39="FAILED",K39="FAILED"),"FAILED",IF(OR(I39="PASSED",K39="PASSED"),"PASSED",IF(OR(I39="IN_PROGRESS",K39="IN_PROGRESS"),"IN_PROGRESS",IF(OR(I39="BLOCKED",K39="BLOCKED"),"BLOCKED","NOT_STARTED"))))) -> NOT_STARTED | I39: NOT_STARTED | J39: NO | K39: NOT_STARTED | L39: §4.6 | M39: partner-platform-prd-v1.8.md | O39: Trang Le | Q39: Validate the UI flow for renewal this quarter so that only qualifying clients are shown. Scope covers the post-close client list, client health detail, renewal actions, and MSP consent/access behavior, authenticated partner/SA role access as applicable, visible copy/state, primary CTA behavior, and PRD coverage §4.6. Out of scope: unrelated modules and deep backend calculation beyond the data needed to prove this case. | R39: 1. Navigate to My Clients with active client fixtures including healthy, at-risk, and renewing clients. 2. Apply the action/filter/search: Renewal This Quarter. 3. Verify client rows show name, ARR, health, renewal date, and modules. 4. Confirm only qualifying clients are shown and counts/tabs match the fixture. 5. Clear filters and confirm the complete client list returns. | S39: 4.6
C40: PARTNER_UI_MY_CLIENTS_008 | D40: Filter - Health At Risk - At-risk clients are shown | E40: Functional | F40: P2 | G40: Major | H40: =IF(J40="No",I40,IF(OR(I40="FAILED",K40="FAILED"),"FAILED",IF(OR(I40="PASSED",K40="PASSED"),"PASSED",IF(OR(I40="IN_PROGRESS",K40="IN_PROGRESS"),"IN_PROGRESS",IF(OR(I40="BLOCKED",K40="BLOCKED"),"BLOCKED","NOT_STARTED"))))) -> NOT_STARTED | I40: NOT_STARTED | J40: NO | K40: NOT_STARTED | L40: §1.3, §4.6 | M40: partner-platform-prd-v1.8.md | O40: Trang Le | Q40: Validate the UI flow for health at risk so that at-risk clients are shown. Scope covers the post-close client list, client health detail, renewal actions, and MSP consent/access behavior, authenticated partner/SA role access as applicable, visible copy/state, primary CTA behavior, and PRD coverage §1.3, §4.6. Out of scope: unrelated modules and deep backend calculation beyond the data needed to prove this case. | R40: 1. Navigate to My Clients with active client fixtures including healthy, at-risk, and renewing clients. 2. Apply the action/filter/search: Health At Risk. 3. Verify client rows show name, ARR, health, renewal date, and modules. 4. Confirm at-risk clients are shown and counts/tabs match the fixture. 5. Clear filters and confirm the complete client list returns. | S40: 4.6
C41: PARTNER_UI_MY_CLIENTS_009 | D41: Search - Find client by name - Matching clients are displayed | E41: Functional | F41: P2 | G41: Major | H41: =IF(J41="No",I41,IF(OR(I41="FAILED",K41="FAILED"),"FAILED",IF(OR(I41="PASSED",K41="PASSED"),"PASSED",IF(OR(I41="IN_PROGRESS",K41="IN_PROGRESS"),"IN_PROGRESS",IF(OR(I41="BLOCKED",K41="BLOCKED"),"BLOCKED","NOT_STARTED"))))) -> NOT_STARTED | I41: NOT_STARTED | J41: NO | K41: NOT_STARTED | L41: §4.6 | M41: partner-platform-prd-v1.8.md | O41: Trang Le | Q41: Validate the UI flow for find client by name so that matching clients are displayed. Scope covers the post-close client list, client health detail, renewal actions, and MSP consent/access behavior, authenticated partner/SA role access as applicable, visible copy/state, primary CTA behavior, and PRD coverage §4.6. Out of scope: unrelated modules and deep backend calculation beyond the data needed to prove this case. | R41: 1. Navigate to My Clients with active client fixtures including healthy, at-risk, and renewing clients. 2. Apply the action/filter/search: Find client by name. 3. Verify client rows show name, ARR, health, renewal date, and modules. 4. Confirm matching clients are displayed and counts/tabs match the fixture. 5. Clear filters and confirm the complete client list returns. | S41: 4.6
C42: PARTNER_UI_MY_CLIENTS_010 | D42: Display - Blazey client insight - Adoption recommendation appears | E42: Functional | F42: P2 | G42: Major | H42: =IF(J42="No",I42,IF(OR(I42="FAILED",K42="FAILED"),"FAILED",IF(OR(I42="PASSED",K42="PASSED"),"PASSED",IF(OR(I42="IN_PROGRESS",K42="IN_PROGRESS"),"IN_PROGRESS",IF(OR(I42="BLOCKED",K42="BLOCKED"),"BLOCKED","NOT_STARTED"))))) -> NOT_STARTED | I42: NOT_STARTED | J42: NO | K42: NOT_STARTED | L42: §1.3, §4.6 | M42: partner-platform-prd-v1.8.md | O42: Trang Le | Q42: Validate the UI flow for blazey client insight so that adoption recommendation appears. Scope covers the post-close client list, client health detail, renewal actions, and MSP consent/access behavior, authenticated partner/SA role access as applicable, visible copy/state, primary CTA behavior, and PRD coverage §1.3, §4.6. Out of scope: unrelated modules and deep backend calculation beyond the data needed to prove this case. | R42: 1. Open My Clients and select a seeded client such as Meridian Ltd. 2. Navigate to the Client Health Detail page. 3. Verify ARR, renewal, adoption/usage, module health, ticket summary, and CSM/owner context are visible. 4. Confirm Blazey insight or renewal recommendation appears when the fixture is at risk. 5. Verify CTA behavior does not expose restricted client data. | S42: 4.6
...

Sheet Regression Suite
A1: REGRESSION SUITE — MODULE STATUS SUMMARY
A2: Item | B2: Description | C2: Summary
A3: TOTAL | B3: Total number of tests | C3: =SUM(C4:C8) -> 119
A4: PASSED | B4: Number of tests PASSED | C4: =COUNTIF('Regression Suite'!G13:G999,"PASSED") -> 0
A5: FAILED | B5: Number of tests FAILED | C5: =COUNTIF('Regression Suite'!G13:G999,"FAILED") -> 0
A6: NOT_STARTED | B6: Number of tests not started | C6: =COUNTIF('Regression Suite'!G13:G999,"NOT_STARTED") -> 118
A7: IN_PROGRESS | B7: Number currently being tested | C7: =COUNTIF('Regression Suite'!G13:G999,"IN_PROGRESS") -> 0
A8: BLOCKED | B8: Tests that could not be executed | C8: =COUNTIF('Regression Suite'!G13:G999,"BLOCKED") -> 1
A11: REGRESSION SUITE — P1 Test Cases (All Modules)
A12: Auto-compiled from all P1 TCs across active modules | Run before every release
A13: TC ID | B13: Module | C13: Test Case Name | D13: Type (UI/API) | E13: Priority | F13: Owner | G13: Automation Status | H13: Automation TC Mapping
A14: Partner Platform
A15: PARTNER_UI_PARTNER_PORTAL_SHELL_001 | B15: Partner Platform | C15: Navigate - Open main menu routes - Correct page content is shown | D15: UI | E15: P1 | F15: Trang Le | G15: NOT_STARTED | H15: tests/ui/partner_002
A16: PARTNER_UI_DASHBOARD_001 | B16: Partner Platform | C16: View - Partner shell loads for channel partner - Dashboard is displayed | D16: UI | E16: P1 | F16: Trang Le | G16: NOT_STARTED | H16: tests/ui/partner_001
A17: PARTNER_UI_DASHBOARD_002 | B17: Partner Platform | C17: Render - Dashboard KPI cards available - Actionable metrics are visible | D17: UI | E17: P1 | F17: Trang Le | G17: NOT_STARTED | H17: tests/ui/partner_003
A18: PARTNER_UI_DASHBOARD_003 | B18: Partner Platform | C18: Render - Tier progress exists on dashboard - Progress to next tier is visible | D18: UI | E18: P1 | F18: Trang Le | G18: NOT_STARTED | H18: tests/ui/partner_004
A19: PARTNER_UI_DASHBOARD_004 | B19: Partner Platform | C19: Render - Action Required list has pending tasks - Partner sees next actions | D19: UI | E19: P1 | F19: Trang Le | G19: NOT_STARTED | H19: tests/ui/partner_005
A20: PARTNER_UI_DASHBOARD_005 | B20: Partner Platform | C20: Calculate - Tier qualification dashboard - T12M ARR threshold and next-tier delta are visible | D20: UI | E20: P1 | F20: Trang Le | G20: NOT_STARTED
A21: PARTNER_UI_DASHBOARD_006 | B21: Partner Platform | C21: Warn - Tier downgrade pending - 30-day notice and grace quarter are displayed | D21: UI | E21: P1 | F21: Trang Le | G21: NOT_STARTED
A22: PARTNER_UI_MY_PIPELINE_001 | B22: Partner Platform | C22: Register - Enter valid company details - Wizard advances to contact step | D22: UI | E22: P1 | F22: Trang Le | G22: NOT_STARTED | H22: tests/ui/partner_010
A23: PARTNER_UI_MY_PIPELINE_002 | B23: Partner Platform | C23: Validate - Leave company name blank - Required field error is shown | D23: UI | E23: P1 | F23: Trang Le | G23: NOT_STARTED | H23: tests/ui/partner_011
A24: PARTNER_UI_MY_PIPELINE_003 | B24: Partner Platform | C24: Validate - Enter invalid domain - Domain format error is shown | D24: UI | E24: P1 | F24: Trang Le | G24: NOT_STARTED | H24: tests/ui/partner_012
A25: PARTNER_UI_MY_PIPELINE_004 | B25: Partner Platform | C25: Warn - Domain already exists - Inline active-account warning is shown | D25: UI | E25: P1 | F25: Trang Le | G25: NOT_STARTED | H25: tests/ui/partner_014
A26: PARTNER_UI_MY_PIPELINE_005 | B26: Partner Platform | C26: Submit - Existing domain with warning - Deal enters conflict queue | D26: UI | E26: P1 | F26: Trang Le | G26: NOT_STARTED | H26: tests/ui/partner_015
A27: PARTNER_UI_MY_PIPELINE_006 | B27: Partner Platform | C27: Validate - Enter contact without email - Required field error is shown | D27: UI | E27: P1 | F27: Trang Le | G27: NOT_STARTED | H27: tests/ui/partner_016
A28: PARTNER_UI_MY_PIPELINE_007 | B28: Partner Platform | C28: Validate - Enter malformed email - Email error is shown | D28: UI | E28: P1 | F28: Trang Le | G28: NOT_STARTED | H28: tests/ui/partner_017
A29: PARTNER_UI_MY_PIPELINE_008 | B29: Partner Platform | C29: Select - Choose referral deal type - Direct billing model is implied | D29: UI | E29: P1 | F29: Trang Le | G29: NOT_STARTED | H29: tests/ui/partner_020
A30: PARTNER_UI_MY_PIPELINE_009 | B30: Partner Platform | C30: Select - Choose reseller deal type - Reseller billing path is available | D30: UI | E30: P1 | F30: Trang Le | G30: NOT_STARTED | H30: tests/ui/partner_021
A31: PARTNER_UI_MY_PIPELINE_010 | B31: Partner Platform | C31: Select - Choose co-sell deal type - Co-sell option is captured | D31: UI | E31: P1 | F31: Trang Le | G31: NOT_STARTED | H31: tests/ui/partner_022
A32: PARTNER_UI_MY_PIPELINE_011 | B32: Partner Platform | C32: Confirm - Review registration summary - All entered data is displayed | D32: UI | E32: P1 | F32: Trang Le | G32: NOT_STARTED | H32: tests/ui/partner_023
A33: PARTNER_UI_MY_PIPELINE_012 | B33: Partner Platform | C33: Submit - Valid deal registration - Success response appears within 2 seconds | D33: UI | E33: P1 | F33: Trang Le | G33: NOT_STARTED | H33: tests/ui/partner_024
... A37: PARTNER_UI_MY_PIPELINE_016 | B37: Partner Platform | C37: Accept - Co-sell override proposal - Partner acceptance is recorded | D37: UI | E37: P1 | F37: Trang Le | G37: NOT_STARTED | H37: tests/ui/partner_034
A38: PARTNER_UI_MY_PIPELINE_017 | B38: Partner Platform | C38: Block - Co-sell override under or equal $100K ACV - Override option is unavailable | D38: UI | E38: P1 | F38: Trang Le | G38: NOT_STARTED
A39: PARTNER_UI_MY_PIPELINE_018 | B39: Partner Platform | C39: Require - Co-sell override above $100K ACV - Partner written agreement is required | D39: UI | E39: P1 | F39: Trang Le | G39: NOT_STARTED
A40: PARTNER_UI_MY_CLIENTS_001 | B40: Partner Platform | C40: Click - Action Required renewal CTA - Renewal registration flow opens | D40: UI | E40: P1 | F40: Trang Le | G40: NOT_STARTED | H40: tests/ui/partner_006
A41: PARTNER_UI_MY_CLIENTS_002 | B41: Partner Platform | C41: List - Open My Clients - Post-close clients are displayed | D41: UI | E41: P1 | F41: Trang Le | G41: NOT_STARTED | H41: tests/ui/partner_036
A42: PARTNER_UI_MY_CLIENTS_003 | B42: Partner Platform | C42: Open - Client health detail - ARR, renewal, usage, tickets, and CSM are visible | D42: UI | E42: P1 | F42: Trang Le | G42: NOT_STARTED | H42: tests/ui/partner_040
A43: PARTNER_UI_MY_CLIENTS_004 | B43: Partner Platform | C43: Register - Renewal deal from client detail - Renewal context is prefilled | D43: UI | E43: P1 | F43: Trang Le | G43: NOT_STARTED | H43: tests/ui/partner_041
A44: PARTNER_UI_MY_CLIENTS_005 | B44: Partner Platform | C44: Add - MSP managed client - Provisioning form is shown | D44: UI | E44: P1 | F44: Trang Le | G44: NOT_STARTED | H44: tests/ui/partner_043
A45: PARTNER_UI_MY_CLIENTS_006 | B45: Partner Platform | C45: Toggle - MSP ticket consent default - Consent is off by default | D45: UI | E45: P1 | F45: Trang Le | G45: NOT_STARTED | H45: tests/ui/partner_044
...

Sheet Execution Log
A1: Execution Log
A2: Sprint / Release | B2: Date | C2: Build Version | D2: Module | E2: TC ID | F2: Executor | G2: Result | H2: Note
A3: Sprint 1 | B3: 2026-05-20 | C3: v0.1.0-alpha | D3: Partner Platform | E3: PARTNER_UI_001 | F3: Trang Le | G3: Not Started | H3: Initial smoke run — placeholder

Sheet Test Scope
A1: TEST SCOPE
A2: Document: partner-platform-prd-v1.8 | Last updated: 2026-05-20 | Status: Living Document
A3: ✅ IN SCOPE
A4: Category | B4: Module | C4: Description | D4: Owner | E4: Status
A5: Partner Platform
A6: In Scope | B6: Partner Platform | C6: Partner portal shell: navigation, dashboard, KPI cards, tier progress, action-required list. | D6: QA Team | E6: Active
A7: In Scope | B7: Partner Platform | C7: Deal registration wizard: referral, reseller, co-sell deal types; validation, conflict detection, commission projection. | D7: QA Team | E7: Active
A8: In Scope | B8: Partner Platform | C8: Pipeline management: deal list, filters, deal detail, timeline, notes, documents, BlazeUp rep view. | D8: QA Team | E8: Active
A9: In Scope | B9: Partner Platform | C9: Client health: client list, health detail (ARR, renewal, usage, tickets), MSP managed client provisioning, consent toggle. | D9: QA Team | E9: Active
A10: In Scope | B10: Partner Platform | C10: Commissions: earned/pending/paid totals, commission trace, dispute submission, product failure waiver, payout details. | D10: QA Team | E10: Active
A11: In Scope | B11: Partner Platform | C11: Training & Resources: certifications, learning paths, marketing assets, co-branded deck, ROI calculator, sandbox reset. | D11: QA Team | E11: Active
A12: In Scope | B12: Partner Platform | C12: Team & Referral: team member invite, campaign referral link creation and analytics. | D12: QA Team | E12: Active
A13: In Scope | B13: Partner Platform | C13: SA Partner Module: partner directory, application FSM (staged approval), deal approval/conflict queues, commission config, territory, analytics, ledger approval. | D13: QA Team | E13: Active
A14: In Scope | B14: Partner Platform | C14: Backend APIs: ms-sa-partners endpoints, Kafka events, MongoDB/Redis persistence, commission engine, tenant provisioning, MSP scope guard, audit trail. | D14: QA Team | E14: Active
A15: In Scope | B15: Partner Platform | C15: Security: partner JWT separation, cross-partner isolation, MFA gates, MSP consent enforcement, SA two-eye approvals, data residency. | D15: QA Team | E15: Active
A17: 🚫 OUT OF SCOPE
A18: Category | B18: Module | C18: Description | D18: Owner | E18: Status
A19: Pack Partner
A20: Out of Scope | B20: Pack Partner | C20: Pack Partner marketplace features — only separation from Channel Partner accounts is validated. | D20: N/A | E20: Excluded
A21: Partner Platform
A22: Out of Scope | B22: Partner Platform | C22: Final Legal/Compliance decisions pending sign-off — related test cases are placeholders only. | D22: N/A | E22: Excluded
A23: Out of Scope | B23: Partner Platform | C23: Exact commission rates/window durations for NN/EN/EE stages — SA will configure values before launch; exact figures not testable yet. | D23: N/A | E23: Pending
A24: Out of Scope | B24: Partner Platform | C24: Third-party training platform vendor behavior — deferred until build-vs-buy decision is finalized. | D24: N/A | E24: Pending
A25: Other Modules
A26: Out of Scope | B26: Other Modules | C26: 9 remaining modules (CRM, etc.) — not yet assigned; will be added as requirements are provided. | D26: N/A | E26: Pending
A28: 📌 ASSUMPTIONS
A29: Category | B29: Module | C29: Description | D29: Owner | E29: Status
A30: All Modules
A31: Assumption | B31: All Modules | C31: This is a living document. New modules will be added as requirements are provided by the team. | D31: QA Team | E31: Active
A32: In Scope | B32: Partner Platform | C32: Requirement-phase automation mappings are placeholders; executable automation will be updated after requirements stabilize. | D32: QA Team | E32: Active
A33: Partner Platform
A34: Assumption | B34: Partner Platform | C34: All test statuses default to Not Started. Status logic: Fail if any = Fail; Pass if Manual = Pass and Automation = Pass/Not Started; else Not Started. | D34: QA Team | E34: Active
A35: Assumption | B35: Partner Platform | C35: Automation mapping IDs (e.g. tests/ui/partner_001) are placeholders — replace with real script paths when automation is implemented. | D35: QA Team | E35: Active
A36: Assumption | B36: Partner Platform | C36: partner.blazeup.ai (dogfood tenant) is the test target. Auth Phase 0 hooks/mocks are used for non-auth slices; live partner auth tested only after auth gate lands. | D36: Dev Team | E36: Active
A38: 🔑 ENTRY & EXIT CRITERIA
A39: Category | B39: Module | C39: Description | D39: Owner | E39: Status
A40: Partner Platform
A41: Entry Criteria | B41: Partner Platform | C41: PRD v1.8 is baselined and available to QA team. | D41: PM | E41: Active
A42: Entry Criteria | B42: Partner Platform | C42: Test environment is deployed: Partner Portal, SA Partner Module, ms-sa-partners, dogfood CRM bridge, tenant provisioning, billing, Kafka test topics. | D42: Dev Team | E42: Active
A43: Entry Criteria | B43: Partner Platform | C43: Seed data is ready: partners, deals, clients, commissions, sandbox profiles, conflict fixtures. | D43: Dev Team | E43: Active
...
